Workbook

Sheet 背景
T1: 人物背景 Background | AP1: =IF(E5="","请选择背景",IF(AND(V3<>"",V4=""),"个性需两条",""))
B3: 角色 | E3: =IF(主要!D3="","",主要!D3) -> 瑞茵.戴派 | R3: 个性 | V3: 喜欢喝酒，不拘小节
B4: 玩家 | E4: =IF(主要!D4="","",主要!D4) -> 人心比痔疮更可怕 | V4: 吃苦耐劳，时常为了寻找神奇生物四处乱跑去乡下的树林
B5: 背景 | E5: 园丁 | R5: 理想 | V5: 成为纽特那样的神奇动物学家
B6: 故乡 | E6: 洞背村 | R6: 羁绊 | V6: 父母被食死徒折磨疯了，还在icu，所以是由外婆外公带大的
B7: 信仰 | R7: 缺点 | V7: 邋遢，不修边幅
R8: 背景原因
B9: 发色 | E9: 浅咖色 | R9: =IF(背景数据!F96=0,"",背景数据!F96)
B10: 瞳色 | E10: 绿色
B11: 肤色 | E11: 白 | R11: 职业原因 | V11: 很神必，一个喜欢神奇动物学的人被分到了拉文克劳
B12: 其他 | R12: =IF(背景数据!I8=0,"",背景数据!I8) | V12: 喜欢研究不同种类的神奇动物知识，还想把它们按照某个体系分类
R13: =IF(背景数据!I14=0,"",背景数据!I14)
B14: 人物 衣装 外貌 描述 | E14: 戴着大眼镜片的短头发浅咖发色少女，喜欢把头发变成小辫，留着雷霆齐刘海，校服不太喜欢好好穿，眼底有黑圆圈是因为偶尔宿醉。 | R14: =IF(背景数据!I20=0,"",背景数据!I20)
R15: =IF(背景数据!I26=0,"",背景数据!I26)
R16: =IF(背景数据!I46=0,"",背景数据!I46)
R17: =IF(背景数据!I58=0,"",背景数据!I58)
R19: 出生预兆
R20: =IF(赠礼数据!D2=0,"",赠礼数据!D2)
R21: =IF(赠礼数据!D10=0,"",赠礼数据!D10)
R22: 龙类纽带
R24: 背景故事 | V24: 同纳威，但是区别是家里确实家底十分雄厚，并且由外公外婆带大，生长于英国郊外的一个小村庄，叫做洞背村，家里是做酒厂的，酒的质量非常高，在巫师界十分出名，导致小时候瑞茵就成了半个酒鬼，酒量很好，经常喝完酒一拍脑袋即兴出门去观察动物，为此挨过不少揍，因为家里有钱，在村里算是街头一霸，孩子王，会用魔法烟花点燃乡下农户养的猪屁股，长大了之后稍微收敛了一点，但是依旧死性不改。
B45: 人物形象
B47: 语言 | E47: 英语

Sheet 主要
O1: DND 5E 人物卡 <New Edition v1.0.0> | AG1: 推荐在电脑上使用Excel2010及以后版本打开本卡
AV2: 小工具
B3: 角色 | D3: 瑞茵.戴派 | P3: 经验 | R3: 0 | Y3: =IF(R3="",1,LOOKUP($R$3,综合数据!D:D,综合数据!C:C)) -> 1 | AW3: 1级 | AY3: 2级 | BA3: 3级 | BC3: 4级 | BE3: 5级 | BG3: 6级 | BI3: 7级 | BK3: 8级 | BM3: 9级 | BO3: 10级
B4: 玩家 | D4: 人心比痔疮更可怕 | P4: 主职 | R4: 秘学士 | V4: 神奇动物 | Y4: 1 | AV4: 生命值小工具 | AW4: 8
P5: =综合数据!H2 -> 0
B6: 种族 | D6: 拉文克劳 | J6: 性别 | L6: 女 | P6: 兼职 | AW6: 11级 | AY6: 12级 | BA6: 13级 | BC6: 14级 | BE6: 15级 | BG6: 16级 | BI6: 17级 | BK6: 18级 | BM6: 19级 | BO6: 20级
B7: 亚种 | J7: 年龄 | L7: 11
B9: 身高 | D9: 145 | J9: 阵营 | L9: 混乱中立 | S9: 熟练 | U9: =IFERROR(VLOOKUP(Y3,综合数据!C:E,3,0)+Y10,2) -> 2 | Y9: 其他 | AW9: 调整值 | BA9: 角色等级 | BE9: 生命总值 | BH9: 仅需填入每级生命骰结果 自动结算各项调整值
B10: 体重 | J10: 赠礼 | X10: < | AW10: =R16+综合数据!F2 -> 1 | BA10: =COUNTA(AW4:BP4,AW7:BP7) -> 1 | BE10: =SUM(综合数据!F3:F22)+IF(COUNTIF(职业数据!AD16:AD18,职业数据!B11),职业数据!AG11,0) -> 9
M12: 属性 | U12: =IF(D6="","请选择种族",IF(种族数据!U18=1,"未选亚种",IF(种族数据!T18=0,"错误亚种",""))) | BD12: 属性分布
B13: 熟练 | F13: 总值 | I13: 初始值 | K13: 种族 | M13: 成长 | O13: 修正 | R13: 调整值 | T13: 豁免 | W13: 修正 | Y13: 临时
C14: 力量 | F14: =SUM(I14:P14) -> 8 | H14: < | I14: 8 | Q14: > | R14: =INT(F14/2-5) -> -1 | T14: =INT(F14/2-5)+IF(综合数据!J1=TRUE,$U$9,0)+SUM(W14:Z14) -> -1 | V14: <
C15: 敏捷 | F15: =SUM(I15:P15) -> 15 | H15: < | I15: 14 | K15: 1 | Q15: > | R15: =INT(F15/2-5) -> 2 | T15: =INT(F15/2-5)+IF(综合数据!K1=TRUE,$U$9,0)+SUM(W15:Z15) -> 2 | V15: <
C16: 体质 | F16: =SUM(I16:P16) -> 13 | H16: < | I16: 13 | Q16: > | R16: =INT(F16/2-5) -> 1 | T16: =INT(F16/2-5)+IF(综合数据!L1=TRUE,$U$9,0)+SUM(W16:Z16) -> 1 | V16: <
C17: 智力 | F17: =SUM(I17:P17) -> 18 | H17: < | I17: 17 | K17: 1 | Q17: > | R17: =INT(F17/2-5) -> 4 | T17: =INT(F17/2-5)+IF(综合数据!M1=TRUE,$U$9,0)+SUM(W17:Z17) -> 4 | V17: <
C18: 感知 | F18: =SUM(I18:P18) -> 17 | H18: < | I18: 16 | K18: 1 | Q18: > | R18: =INT(F18/2-5) -> 3 | T18: =INT(F18/2-5)+IF(综合数据!N1=TRUE,$U$9,0)+SUM(W18:Z18) -> 3 | V18: <
C19: 魅力 | F19: =SUM(I19:P19) -> 10 | H19: < | I19: 10 | Q19: > | R19: =INT(F19/2-5) -> 0 | T19: =INT(F19/2-5)+IF(综合数据!O1=TRUE,$U$9,0)+SUM(W19:Z19) -> 0 | V19: <
B21: 战斗
G22: 临时 | N22: Now | Q22: Max
B23: 先攻 | D23: =SUM(R15+G23)+IF(COUNTIF(专长数据!E2:E7,专长数据!A3),5,0)+IF(COUNTIF(职业数据!AD16:AD18,职业数据!D9),R18,0)+IF(COUNTIF(职业数据!AD16:AD18,职业数据!H10),R19,0)+IF(OR(COUNTIF(职业数据!AD16:AD18,职业数据!K13),COUNTIF(职业数据!AD16:AD18,职业数据!L13)),R17,0) -> -3 | F23: < | G23: -5 | J23: HP | M23: 9 | P23: / | Q23: =BE10 -> 9 | V23: 临时 HP | X23: 0
J25: =M23 -> 9
B26: AC | D26: {=IF(AB39="",0,AB39)+IF(种族数据!V3=种族数据!A34,0,IF(AND(装备数据!AO2<>"",装备数据!AO2<R15),装备数据!AO2,IF(装备数据!AO2=0,0,R15)))+G26+IF(装备数据!AS2=TRUE,IF(AP39="",0,AP39),0)+IF(AND(装备数据!AL2=装备数据!J4,装备数据!K4=10),MAX(IF(职业数据!AG2>=1,R16,0),IF(AND(职业数据!AG7>=1,装备数据!AS2=FALSE),R18,0),0),0)+IF(D6=种族数据!A25,M28R16-R15,0)} -> 11 | F26: < | G26: -1 | J26: HD | L26: 2 | N26: / | O26: =IF(Y4<=0,"",Y4) -> 1 | Q26: =职业数据!AS6 | S26: + | V26: /
D28: 持盾 | G28: 其他 | I28: 死亡豁免成功 | P28: 失败 | AB28: 画像
B29: DC | D29: =SUM(8+U9+G29+IF(F31=C14,R14,IF(F31=C15,R15,IF(F31=C16,R16,IF(F31=C17,R17,IF(F31=C18,R18,IF(F31=C19,R19,0))))))) -> 14 | F29: < | J29: 抗性 | AB29: 免疫
AV30: 技能分布
B31: DC属性 | F31: 智力
J32: 体型 | L32: 中型 | P32: 速度 | R32: 30 | AB32: 优势
B34: 被动察觉 | F34: =SUM(10+R18) -> 13 | J34: 荒野形态 | S34: 特殊能力 | AB34: 劣势
B37: 技能 | L37: =IF(AND(COUNTIF(职业数据!AC16:AC18,职业数据!A7),装备数据!AU6=0),"无法使用武僧武器",IF(OR(AND(COUNTIF(L41:N45,"专用*")>=1,装备数据!AU7=0),AND(COUNTIF(L41:N45,"剑圣*")>=1,装备数据!AU7<2),AND(COUNTIF(L41:N45,"匠师*")>=1,装备数据!AU9=0),AND(COUNTIF(L41:N45,"咒术")>=1,装备数据!AU8=0)),"无法使用职业武器",IF(装备数据!AW3=0,"护甲种类有误",IF(AND(种族数据!V3=种族数据!A34,装备数据!AW2=1),"龟人无法使用护甲",IF(装备数据!R47<=-1,"同调装备过多",""))))) -> 护甲种类有误 | S37: 装备 | W37: =IF(COUNTIF(装备数据!R30:R45,TRUE)=0,"","已同调的装备："&COUNTIF(装备数据!R30:R45,TRUE)&"/"&IF(职业数据!AG14>=18,6,IF(职业数据!AG14>=14,5,IF(职业数据!AG14>=10,4,3)))) | AD37: 快捷战斗
A38: 熟练 | C38: 力量系 | F38: 修正 | I38: 总值 | L38: 护甲 | O38: 同调 | P38: 名称 | U38: 特性 | X38: 熟练 | Y38: 重量 | AA38: 基础AC | AD38: 最大敏捷 | AH38: 劣势 | AJ38: 护盾 | AL38: 同调 | AN38: 名称 | AP38: AC | AR38: 重量 | AU38: 熟练
C39: 运动 | H39: > | I39: =$R$14+IF(综合数据!R2=TRUE,$U$9,0)+F39 -> -1 | AA39: > | AB39: =装备数据!$AM$2 -> 10 | AH39: 沉重
C40: 敏捷系 | L40: 武器 | O40: 同调 | P40: 名称 | T40: 特性 | Y40: 重量 | AB40: 熟练 | AC40: 命中骰 | AF40: 加值 | AH40: 基础伤害 | AK40: 加值 | AN40: 类型 | AQ40: 弹药 | AT40: 计重
C41: 体操 | H41: > | I41: 4 | L41: 魔杖 | S41: 凤凰羽毛、梧桐木，13.5英寸，刚硬 | Y41: 1 | AA41: > | AC41: =IF(L41="","","D20"&IF(装备数据!AR6>0,"+","")&IF(装备数据!AR6<>0,装备数据!AR6,"")) -> D20 | AF41: =IF(AG41>0,"+","") | AK41: =IF(AL41>0,"+","") | AQ41: 箭
C42: 巧手 | H42: > | I42: 4 | AA42: > | AC42: =IF(L42="","","D20"&IF(装备数据!AR7>0,"+","")&IF(装备数据!AR7<>0,装备数据!AR7,"")) | AF42: =IF(AG42>0,"+","") | AK42: =IF(AL42>0,"+","") | AQ42: 吹
C43: 隐匿 | H43: > | I43: 6 | N43: > | AA43: > | AC43: =IF(L43="","","D20"&IF(装备数据!AR8>0,"+","")&IF(装备数据!AR8<>0,装备数据!AR8,"")) | AF43: =IF(AG43>0,"+","") | AK43: =IF(AL43>0,"+","") | AQ43: 矢
C44: 智力系 | N44: > | AA44: > | AC44: =IF(L44="","","D20"&IF(装备数据!AR9>0,"+","")&IF(装备数据!AR9<>0,装备数据!AR9,"")) | AF44: =IF(AG44>0,"+","") | AK44: =IF(AL44>0,"+","") | AQ44: 投
C45: 奥秘 | H45: > | I45: =$R$17+IF(综合数据!R6=TRUE,$U$9,0)+F45 -> 4 | N45: > | AA45: > | AC45: =IF(L45="","","D20"&IF(装备数据!AR10>0,"+","")&IF(装备数据!AR10<>0,装备数据!AR10,"")) | AF45: =IF(AG45>0,"+","") | AK45: =IF(AL45>0,"+","") | AQ45: 弹
C46: 历史 | H46: > | I46: 2 | L46: 其他 | O46: 同调 | Q46: 名称 | V46: 特性 | AA46: 重量 | AV46: 异常状态及选开属性
C47: 调查 | F47: 2 | H47: > | I47: =$R$17+IF(综合数据!R8=TRUE,$U$9,0)+F47 -> 6 | L47: 身体 | N47: > | AK47: 法术 | AM47: =IF(SUMPRODUCT(--(AO52:AO60>AR52:AR60)),"法术位超上限","") | AW47: 异常
C48: 自然 | H48: > | I48: =$R$17+IF(综合数据!R9=TRUE,$U$9,0)+F48 -> 4 | L48: 双手 | N48: > | AD48: 施法关键属性 | AH48: 命中骰 | AK48: 加值 | AO48: 法术DC | AQ48: 加值 | AX48: 目盲 | BB48: 魅惑 | BF48: 耳聋 | BJ48: 恐慌 | BN48: 擒抱
...

Sheet 背包
A1: 背包 Inventory
B3: 背包 | P3: =IF(AND(COUNTA(B5:H14)+COUNTA(B16:H25)>0,B3=""),"请选择容器",IF(V3-装备数据!Z11>装备数据!Y11,"容量超上限","")) | V3: =装备数据!Z11+SUMPRODUCT(S5:T25,V5:W25) -> 5 | Y3: 小包 | AM3: =IF(AND(COUNTA(Y5:AE14)+COUNTA(Y16:AE25)>0,Y3=""),"请选择容器",IF(AS3-装备数据!Z32>装备数据!Y32,"容量超上限","")) | AS3: =装备数据!Z32+SUMPRODUCT(AP5:AQ25,AS5:AT25) -> 1 | AW3: 杂物袋1 | BT3: 杂物袋2
B4: 名称 | I4: 描述 | S4: 重量 | V4: 数量 | Y4: 名称 | AF4: 描述 | AP4: 重量 | AS4: 数量
U5: × | AR5: ×
U6: × | AR6: ×
U7: × | AR7: ×
U8: × | AR8: ×
U9: × | AR9: ×
U10: × | AR10: ×
U11: × | AR11: ×
U12: × | AR12: ×
U13: × | AR13: ×
U14: × | AR14: ×
U16: × | AR16: ×
U17: × | AR17: ×
... U25: × | AR25: ×
B27: 无效 | H27: 次元袋 | P27: =IF(U27>500,"超载","") | U27: =SUMPRODUCT(S29:T82,V29:W82) -> 0 | Y27: 无效 | AE27: 霍华德的便利袋 | AM27: =IF(AR27>120,"超载","") | AR27: =SUMPRODUCT(AP29:AQ82,AS29:AT82) -> 0
B28: 名称 | I28: 描述 | S28: 重量 | V28: 数量 | Y28: 名称 | AF28: 描述 | AP28: 重量 | AS28: 数量
U29: × | AR29: ×
U30: × | AR30: ×
U31: × | AR31: ×
U32: × | AR32: ×
U33: × | AR33: ×
U34: × | AR34: ×
U35: × | AR35: ×
U36: × | AR36: ×
U37: × | AR37: ×
U38: × | AR38: ×
U40: × | AR40: ×
U41: × | AR41: ×
... U82: × | AR82: ×

Sheet 法术书
T2: 书页标签
C3: =IF(Y5<>"",Y5,V5)
T4: 法术书 | V4: 法术书1 | W4: 页码 | Y4: =101-法术数据!AV10 -> 1
U5: =IF(V5="","","Lv") | V5: =IF(V4="法术书1",VLOOKUP(101-法术数据!AV10,法术数据!AJ:AK,2,FALSE),IF(V4="法术书2",VLOOKUP(201-法术数据!AV10,法术数据!AJ:AK,2,FALSE),IF(V4="法术书3",VLOOKUP(301-法术数据!AV10,法术数据!AJ:AK,2,FALSE),"空白标签"))) | W5: 优先读取
U6: =IFERROR(VLOOKUP(V5,法术数据!B:P,15,FALSE),"")
T7: 法术书1 | Z7: 法术书2 | AF7: 法术书3
C8: =IF(C3="","",VLOOKUP(C3,法术数据!B:C,2,FALSE)) | O8: =IF(C3="","","出自："&VLOOKUP(C3,法术数据!B:Q,16,FALSE)) | T8: =IF(V8="","",法术数据!AJ2) | U8: =IFERROR(VLOOKUP(V8,法术数据!B:P,15,FALSE),"") | W8: =IF(Y8="","",法术数据!AJ52) | X8: =IFERROR(VLOOKUP(Y8,法术数据!B:P,15,FALSE),"") | Z8: =IF(AB8="","",法术数据!AJ2) | AA8: =IFERROR(VLOOKUP(AB8,法术数据!B:P,15,FALSE),"") | AC8: =IF(AE8="","",法术数据!AJ52) | AD8: =IFERROR(VLOOKUP(AE8,法术数据!B:P,15,FALSE),"") | AF8: =IF(AH8="","",法术数据!AJ2) | AG8: =IFERROR(VLOOKUP(AH8,法术数据!B:P,15,FALSE),"") | AI8: =IF(AK8="","",法术数据!AJ52) | AJ8: =IFERROR(VLOOKUP(AK8,法术数据!B:P,15,FALSE),"")
C9: =IF(C3="","","施法时间： "&VLOOKUP(C3,法术数据!B:F,5,FALSE)&IF(VLOOKUP(C3,法术数据!B:D,3,FALSE)=1,"（仪式）","")) | O9: =IF(C3="","",VLOOKUP(VLOOKUP(C3,法术数据!B:P,15,FALSE),CHOOSE({1,2},法术数据!AI2:AI11,法术数据!AH2:AH11),2,FALSE)&" / "&VLOOKUP(C3,法术数据!B:E,4,FALSE)) | T9: =IF(V9="","",法术数据!AJ3) | U9: =IFERROR(VLOOKUP(V9,法术数据!B:P,15,FALSE),"") | W9: =IF(Y9="","",法术数据!AJ53) | X9: =IFERROR(VLOOKUP(Y9,法术数据!B:P,15,FALSE),"") | Z9: =IF(AB9="","",法术数据!AJ3) | AA9: =IFERROR(VLOOKUP(AB9,法术数据!B:P,15,FALSE),"") | AC9: =IF(AE9="","",法术数据!AV53) | AD9: =IFERROR(VLOOKUP(AE9,法术数据!B:P,15,FALSE),"") | AF9: =IF(AH9="","",法术数据!AJ3) | AG9: =IFERROR(VLOOKUP(AH9,法术数据!B:P,15,FALSE),"") | AI9: =IF(AK9="","",法术数据!AT53) | AJ9: =IFERROR(VLOOKUP(AK9,法术数据!B:P,15,FALSE),"")
T10: =IF(V10="","",法术数据!AJ4) | U10: =IFERROR(VLOOKUP(V10,法术数据!B:P,15,FALSE),"") | W10: =IF(Y10="","",法术数据!AJ54) | X10: =IFERROR(VLOOKUP(Y10,法术数据!B:P,15,FALSE),"") | Z10: =IF(AB10="","",法术数据!AJ4) | AA10: =IFERROR(VLOOKUP(AB10,法术数据!B:P,15,FALSE),"") | AC10: =IF(AE10="","",法术数据!AJ54) | AD10: =IFERROR(VLOOKUP(AE10,法术数据!B:P,15,FALSE),"") | AF10: =IF(AH10="","",法术数据!AJ4) | AG10: =IFERROR(VLOOKUP(AH10,法术数据!B:P,15,FALSE),"") | AI10: =IF(AK10="","",法术数据!AJ54) | AJ10: =IFERROR(VLOOKUP(AK10,法术数据!B:P,15,FALSE),"")
C11: =IF(C3="","","法术成分："&IF(VLOOKUP(C3,法术数据!B:H,7,FALSE)=1," 言语 ","")&IF(VLOOKUP(C3,法术数据!B:I,8,FALSE)=1," 姿势 ","")&IF(VLOOKUP(C3,法术数据!B:J,9,FALSE)=1," 材料 ","")) | K11: =IF(C3="","","施法距离： "&(VLOOKUP(C3,法术数据!B:G,6,FALSE))) | T11: =IF(V11="","",法术数据!AJ5) | U11: =IFERROR(VLOOKUP(V11,法术数据!B:P,15,FALSE),"") | W11: =IF(Y11="","",法术数据!AJ55) | X11: =IFERROR(VLOOKUP(Y11,法术数据!B:P,15,FALSE),"") | Z11: =IF(AB11="","",法术数据!AJ5) | AA11: =IFERROR(VLOOKUP(AB11,法术数据!B:P,15,FALSE),"") | AC11: =IF(AE11="","",法术数据!AV55) | AD11: =IFERROR(VLOOKUP(AE11,法术数据!B:P,15,FALSE),"") | AF11: =IF(AH11="","",法术数据!AJ5) | AG11: =IFERROR(VLOOKUP(AH11,法术数据!B:P,15,FALSE),"") | AI11: =IF(AK11="","",法术数据!AT55) | AJ11: =IFERROR(VLOOKUP(AK11,法术数据!B:P,15,FALSE),"")
T12: =IF(V12="","",法术数据!AJ6) | U12: =IFERROR(VLOOKUP(V12,法术数据!B:P,15,FALSE),"") | W12: =IF(Y12="","",法术数据!AJ56) | X12: =IFERROR(VLOOKUP(Y12,法术数据!B:P,15,FALSE),"") | Z12: =IF(AB12="","",法术数据!AJ6) | AA12: =IFERROR(VLOOKUP(AB12,法术数据!B:P,15,FALSE),"") | AC12: =IF(AE12="","",法术数据!AJ56) | AD12: =IFERROR(VLOOKUP(AE12,法术数据!B:P,15,FALSE),"") | AF12: =IF(AH12="","",法术数据!AJ6) | AG12: =IFERROR(VLOOKUP(AH12,法术数据!B:P,15,FALSE),"") | AI12: =IF(AK12="","",法术数据!AJ56) | AJ12: =IFERROR(VLOOKUP(AK12,法术数据!B:P,15,FALSE),"")
C13: =IF(C3="","",IF(VLOOKUP(C3,法术数据!B:K,10,FALSE)="","","触媒： "&VLOOKUP(C3,法术数据!B:K,10,FALSE))&IF(VLOOKUP(C3,法术数据!B:J,9,FALSE)=2,CHAR(10),"")&IF(VLOOKUP(C3,法术数据!B:L,11,FALSE)="","","耗材： "&(VLOOKUP(C3,法术数据!B:L,11,FALSE)))) | T13: =IF(V13="","",法术数据!AJ7) | U13: =IFERROR(VLOOKUP(V13,法术数据!B:P,15,FALSE),"") | W13: =IF(Y13="","",法术数据!AJ57) | X13: =IFERROR(VLOOKUP(Y13,法术数据!B:P,15,FALSE),"") | Z13: =IF(AB13="","",法术数据!AJ7) | AA13: =IFERROR(VLOOKUP(AB13,法术数据!B:P,15,FALSE),"") | AC13: =IF(AE13="","",法术数据!AV57) | AD13: =IFERROR(VLOOKUP(AE13,法术数据!B:P,15,FALSE),"") | AF13: =IF(AH13="","",法术数据!AJ7) | AG13: =IFERROR(VLOOKUP(AH13,法术数据!B:P,15,FALSE),"") | AI13: =IF(AK13="","",法术数据!AT57) | AJ13: =IFERROR(VLOOKUP(AK13,法术数据!B:P,15,FALSE),"")
T14: =IF(V14="","",法术数据!AJ8) | U14: =IFERROR(VLOOKUP(V14,法术数据!B:P,15,FALSE),"") | W14: =IF(Y14="","",法术数据!AJ58) | X14: =IFERROR(VLOOKUP(Y14,法术数据!B:P,15,FALSE),"") | Z14: =IF(AB14="","",法术数据!AJ8) | AA14: =IFERROR(VLOOKUP(AB14,法术数据!B:P,15,FALSE),"") | AC14: =IF(AE14="","",法术数据!AJ58) | AD14: =IFERROR(VLOOKUP(AE14,法术数据!B:P,15,FALSE),"") | AF14: =IF(AH14="","",法术数据!AJ8) | AG14: =IFERROR(VLOOKUP(AH14,法术数据!B:P,15,FALSE),"") | AI14: =IF(AK14="","",法术数据!AJ58) | AJ14: =IFERROR(VLOOKUP(AK14,法术数据!B:P,15,FALSE),"")
T15: =IF(V15="","",法术数据!AJ9) | U15: =IFERROR(VLOOKUP(V15,法术数据!B:P,15,FALSE),"") | W15: =IF(Y15="","",法术数据!AJ59) | X15: =IFERROR(VLOOKUP(Y15,法术数据!B:P,15,FALSE),"") | Z15: =IF(AB15="","",法术数据!AJ9) | AA15: =IFERROR(VLOOKUP(AB15,法术数据!B:P,15,FALSE),"") | AC15: =IF(AE15="","",法术数据!AV59) | AD15: =IFERROR(VLOOKUP(AE15,法术数据!B:P,15,FALSE),"") | AF15: =IF(AH15="","",法术数据!AJ9) | AG15: =IFERROR(VLOOKUP(AH15,法术数据!B:P,15,FALSE),"") | AI15: =IF(AK15="","",法术数据!AT59) | AJ15: =IFERROR(VLOOKUP(AK15,法术数据!B:P,15,FALSE),"")
T16: =IF(V16="","",法术数据!AJ10) | U16: =IFERROR(VLOOKUP(V16,法术数据!B:P,15,FALSE),"") | W16: =IF(Y16="","",法术数据!AJ60) | X16: =IFERROR(VLOOKUP(Y16,法术数据!B:P,15,FALSE),"") | Z16: =IF(AB16="","",法术数据!AJ10) | AA16: =IFERROR(VLOOKUP(AB16,法术数据!B:P,15,FALSE),"") | AC16: =IF(AE16="","",法术数据!AJ60) | AD16: =IFERROR(VLOOKUP(AE16,法术数据!B:P,15,FALSE),"") | AF16: =IF(AH16="","",法术数据!AJ10) | AG16: =IFERROR(VLOOKUP(AH16,法术数据!B:P,15,FALSE),"") | AI16: =IF(AK16="","",法术数据!AJ60) | AJ16: =IFERROR(VLOOKUP(AK16,法术数据!B:P,15,FALSE),"")
T17: =IF(V17="","",法术数据!AJ11) | U17: =IFERROR(VLOOKUP(V17,法术数据!B:P,15,FALSE),"") | W17: =IF(Y17="","",法术数据!AJ61) | X17: =IFERROR(VLOOKUP(Y17,法术数据!B:P,15,FALSE),"") | Z17: =IF(AB17="","",法术数据!AJ11) | AA17: =IFERROR(VLOOKUP(AB17,法术数据!B:P,15,FALSE),"") | AC17: =IF(AE17="","",法术数据!AV61) | AD17: =IFERROR(VLOOKUP(AE17,法术数据!B:P,15,FALSE),"") | AF17: =IF(AH17="","",法术数据!AJ11) | AG17: =IFERROR(VLOOKUP(AH17,法术数据!B:P,15,FALSE),"") | AI17: =IF(AK17="","",法术数据!AT61) | AJ17: =IFERROR(VLOOKUP(AK17,法术数据!B:P,15,FALSE),"")
T18: =IF(V18="","",法术数据!AJ12) | U18: =IFERROR(VLOOKUP(V18,法术数据!B:P,15,FALSE),"") | W18: =IF(Y18="","",法术数据!AJ62) | X18: =IFERROR(VLOOKUP(Y18,法术数据!B:P,15,FALSE),"") | Z18: =IF(AB18="","",法术数据!AJ12) | AA18: =IFERROR(VLOOKUP(AB18,法术数据!B:P,15,FALSE),"") | AC18: =IF(AE18="","",法术数据!AJ62) | AD18: =IFERROR(VLOOKUP(AE18,法术数据!B:P,15,FALSE),"") | AF18: =IF(AH18="","",法术数据!AJ12) | AG18: =IFERROR(VLOOKUP(AH18,法术数据!B:P,15,FALSE),"") | AI18: =IF(AK18="","",法术数据!AJ62) | AJ18: =IFERROR(VLOOKUP(AK18,法术数据!B:P,15,FALSE),"")
C19: =IF(C3="","","持续时间： "&VLOOKUP(C3,法术数据!B:N,13,FALSE)) | O19: =IFERROR(IF(VLOOKUP(C3,法术数据!B:M,12,FALSE)=1,"需要专注",""),"") | T19: =IF(V19="","",法术数据!AJ13) | U19: =IFERROR(VLOOKUP(V19,法术数据!B:P,15,FALSE),"") | W19: =IF(Y19="","",法术数据!AJ63) | X19: =IFERROR(VLOOKUP(Y19,法术数据!B:P,15,FALSE),"") | Z19: =IF(AB19="","",法术数据!AJ13) | AA19: =IFERROR(VLOOKUP(AB19,法术数据!B:P,15,FALSE),"") | AC19: =IF(AE19="","",法术数据!AV63) | AD19: =IFERROR(VLOOKUP(AE19,法术数据!B:P,15,FALSE),"") | AF19: =IF(AH19="","",法术数据!AJ13) | AG19: =IFERROR(VLOOKUP(AH19,法术数据!B:P,15,FALSE),"") | AI19: =IF(AK19="","",法术数据!AT63) | AJ19: =IFERROR(VLOOKUP(AK19,法术数据!B:P,15,FALSE),"")
T20: =IF(V20="","",法术数据!AJ14) | U20: =IFERROR(VLOOKUP(V20,法术数据!B:P,15,FALSE),"") | W20: =IF(Y20="","",法术数据!AJ64) | X20: =IFERROR(VLOOKUP(Y20,法术数据!B:P,15,FALSE),"") | Z20: =IF(AB20="","",法术数据!AJ14) | AA20: =IFERROR(VLOOKUP(AB20,法术数据!B:P,15,FALSE),"") | AC20: =IF(AE20="","",法术数据!AJ64) | AD20: =IFERROR(VLOOKUP(AE20,法术数据!B:P,15,FALSE),"") | AF20: =IF(AH20="","",法术数据!AJ14) | AG20: =IFERROR(VLOOKUP(AH20,法术数据!B:P,15,FALSE),"") | AI20: =IF(AK20="","",法术数据!AJ64) | AJ20: =IFERROR(VLOOKUP(AK20,法术数据!B:P,15,FALSE),"")
T21: =IF(V21="","",法术数据!AJ15) | U21: =IFERROR(VLOOKUP(V21,法术数据!B:P,15,FALSE),"") | W21: =IF(Y21="","",法术数据!AJ65) | X21: =IFERROR(VLOOKUP(Y21,法术数据!B:P,15,FALSE),"") | Z21: =IF(AB21="","",法术数据!AJ15) | AA21: =IFERROR(VLOOKUP(AB21,法术数据!B:P,15,FALSE),"") | AC21: =IF(AE21="","",法术数据!AV65) | AD21: =IFERROR(VLOOKUP(AE21,法术数据!B:P,15,FALSE),"") | AF21: =IF(AH21="","",法术数据!AJ15) | AG21: =IFERROR(VLOOKUP(AH21,法术数据!B:P,15,FALSE),"") | AI21: =IF(AK21="","",法术数据!AT65) | AJ21: =IFERROR(VLOOKUP(AK21,法术数据!B:P,15,FALSE),"")
C22: =IF(C23<>"","法术说明","") | T22: =IF(V22="","",法术数据!AJ16) | U22: =IFERROR(VLOOKUP(V22,法术数据!B:P,15,FALSE),"") | W22: =IF(Y22="","",法术数据!AJ66) | X22: =IFERROR(VLOOKUP(Y22,法术数据!B:P,15,FALSE),"") | Z22: =IF(AB22="","",法术数据!AJ16) | AA22: =IFERROR(VLOOKUP(AB22,法术数据!B:P,15,FALSE),"") | AC22: =IF(AE22="","",法术数据!AJ66) | AD22: =IFERROR(VLOOKUP(AE22,法术数据!B:P,15,FALSE),"") | AF22: =IF(AH22="","",法术数据!AJ16) | AG22: =IFERROR(VLOOKUP(AH22,法术数据!B:P,15,FALSE),"") | AI22: =IF(AK22="","",法术数据!AJ66) | AJ22: =IFERROR(VLOOKUP(AK22,法术数据!B:P,15,FALSE),"")
C23: =IF(C3="","",(VLOOKUP(C3,法术数据!B:O,14,FALSE))) | T23: =IF(V23="","",法术数据!AJ17) | U23: =IFERROR(VLOOKUP(V23,法术数据!B:P,15,FALSE),"") | W23: =IF(Y23="","",法术数据!AJ67) | X23: =IFERROR(VLOOKUP(Y23,法术数据!B:P,15,FALSE),"") | Z23: =IF(AB23="","",法术数据!AJ17) | AA23: =IFERROR(VLOOKUP(AB23,法术数据!B:P,15,FALSE),"") | AC23: =IF(AE23="","",法术数据!AV67) | AD23: =IFERROR(VLOOKUP(AE23,法术数据!B:P,15,FALSE),"") | AF23: =IF(AH23="","",法术数据!AJ17) | AG23: =IFERROR(VLOOKUP(AH23,法术数据!B:P,15,FALSE),"") | AI23: =IF(AK23="","",法术数据!AT67) | AJ23: =IFERROR(VLOOKUP(AK23,法术数据!B:P,15,FALSE),"")
T24: =IF(V24="","",法术数据!AJ18) | U24: =IFERROR(VLOOKUP(V24,法术数据!B:P,15,FALSE),"") | W24: =IF(Y24="","",法术数据!AJ68) | X24: =IFERROR(VLOOKUP(Y24,法术数据!B:P,15,FALSE),"") | Z24: =IF(AB24="","",法术数据!AJ18) | AA24: =IFERROR(VLOOKUP(AB24,法术数据!B:P,15,FALSE),"") | AC24: =IF(AE24="","",法术数据!AJ68) | AD24: =IFERROR(VLOOKUP(AE24,法术数据!B:P,15,FALSE),"") | AF24: =IF(AH24="","",法术数据!AJ18) | AG24: =IFERROR(VLOOKUP(AH24,法术数据!B:P,15,FALSE),"") | AI24: =IF(AK24="","",法术数据!AJ68) | AJ24: =IFERROR(VLOOKUP(AK24,法术数据!B:P,15,FALSE),"")
T25: =IF(V25="","",法术数据!AJ19) | U25: =IFERROR(VLOOKUP(V25,法术数据!B:P,15,FALSE),"") | W25: =IF(Y25="","",法术数据!AJ69) | X25: =IFERROR(VLOOKUP(Y25,法术数据!B:P,15,FALSE),"") | Z25: =IF(AB25="","",法术数据!AJ19) | AA25: =IFERROR(VLOOKUP(AB25,法术数据!B:P,15,FALSE),"") | AC25: =IF(AE25="","",法术数据!AV69) | AD25: =IFERROR(VLOOKUP(AE25,法术数据!B:P,15,FALSE),"") | AF25: =IF(AH25="","",法术数据!AJ19) | AG25: =IFERROR(VLOOKUP(AH25,法术数据!B:P,15,FALSE),"") | AI25: =IF(AK25="","",法术数据!AT69) | AJ25: =IFERROR(VLOOKUP(AK25,法术数据!B:P,15,FALSE),"")
T26: =IF(V26="","",法术数据!AJ20) | U26: =IFERROR(VLOOKUP(V26,法术数据!B:P,15,FALSE),"") | W26: =IF(Y26="","",法术数据!AJ70) | X26: =IFERROR(VLOOKUP(Y26,法术数据!B:P,15,FALSE),"") | Z26: =IF(AB26="","",法术数据!AJ20) | AA26: =IFERROR(VLOOKUP(AB26,法术数据!B:P,15,FALSE),"") | AC26: =IF(AE26="","",法术数据!AJ70) | AD26: =IFERROR(VLOOKUP(AE26,法术数据!B:P,15,FALSE),"") | AF26: =IF(AH26="","",法术数据!AJ20) | AG26: =IFERROR(VLOOKUP(AH26,法术数据!B:P,15,FALSE),"") | AI26: =IF(AK26="","",法术数据!AJ70) | AJ26: =IFERROR(VLOOKUP(AK26,法术数据!B:P,15,FALSE),"")
T27: =IF(V27="","",法术数据!AJ21) | U27: =IFERROR(VLOOKUP(V27,法术数据!B:P,15,FALSE),"") | W27: =IF(Y27="","",法术数据!AJ71) | X27: =IFERROR(VLOOKUP(Y27,法术数据!B:P,15,FALSE),"") | Z27: =IF(AB27="","",法术数据!AJ21) | AA27: =IFERROR(VLOOKUP(AB27,法术数据!B:P,15,FALSE),"") | AC27: =IF(AE27="","",法术数据!AV71) | AD27: =IFERROR(VLOOKUP(AE27,法术数据!B:P,15,FALSE),"") | AF27: =IF(AH27="","",法术数据!AJ21) | AG27: =IFERROR(VLOOKUP(AH27,法术数据!B:P,15,FALSE),"") | AI27: =IF(AK27="","",法术数据!AT71) | AJ27: =IFERROR(VLOOKUP(AK27,法术数据!B:P,15,FALSE),"")
T28: =IF(V28="","",法术数据!AJ22) | U28: =IFERROR(VLOOKUP(V28,法术数据!B:P,15,FALSE),"") | W28: =IF(Y28="","",法术数据!AJ72) | X28: =IFERROR(VLOOKUP(Y28,法术数据!B:P,15,FALSE),"") | Z28: =IF(AB28="","",法术数据!AJ22) | AA28: =IFERROR(VLOOKUP(AB28,法术数据!B:P,15,FALSE),"") | AC28: =IF(AE28="","",法术数据!AJ72) | AD28: =IFERROR(VLOOKUP(AE28,法术数据!B:P,15,FALSE),"") | AF28: =IF(AH28="","",法术数据!AJ22) | AG28: =IFERROR(VLOOKUP(AH28,法术数据!B:P,15,FALSE),"") | AI28: =IF(AK28="","",法术数据!AJ72) | AJ28: =IFERROR(VLOOKUP(AK28,法术数据!B:P,15,FALSE),"")
T29: =IF(V29="","",法术数据!AJ23) | U29: =IFERROR(VLOOKUP(V29,法术数据!B:P,15,FALSE),"") | W29: =IF(Y29="","",法术数据!AJ73) | X29: =IFERROR(VLOOKUP(Y29,法术数据!B:P,15,FALSE),"") | Z29: =IF(AB29="","",法术数据!AJ23) | AA29: =IFERROR(VLOOKUP(AB29,法术数据!B:P,15,FALSE),"") | AC29: =IF(AE29="","",法术数据!AV73) | AD29: =IFERROR(VLOOKUP(AE29,法术数据!B:P,15,FALSE),"") | AF29: =IF(AH29="","",法术数据!AJ23) | AG29: =IFERROR(VLOOKUP(AH29,法术数据!B:P,15,FALSE),"") | AI29: =IF(AK29="","",法术数据!AT73) | AJ29: =IFERROR(VLOOKUP(AK29,法术数据!B:P,15,FALSE),"")
T30: =IF(V30="","",法术数据!AJ24) | U30: =IFERROR(VLOOKUP(V30,法术数据!B:P,15,FALSE),"") | W30: =IF(Y30="","",法术数据!AJ74) | X30: =IFERROR(VLOOKUP(Y30,法术数据!B:P,15,FALSE),"") | Z30: =IF(AB30="","",法术数据!AJ24) | AA30: =IFERROR(VLOOKUP(AB30,法术数据!B:P,15,FALSE),"") | AC30: =IF(AE30="","",法术数据!AJ74) | AD30: =IFERROR(VLOOKUP(AE30,法术数据!B:P,15,FALSE),"") | AF30: =IF(AH30="","",法术数据!AJ24) | AG30: =IFERROR(VLOOKUP(AH30,法术数据!B:P,15,FALSE),"") | AI30: =IF(AK30="","",法术数据!AJ74) | AJ30: =IFERROR(VLOOKUP(AK30,法术数据!B:P,15,FALSE),"")
T31: =IF(V31="","",法术数据!AJ25) | U31: =IFERROR(VLOOKUP(V31,法术数据!B:P,15,FALSE),"") | W31: =IF(Y31="","",法术数据!AJ75) | X31: =IFERROR(VLOOKUP(Y31,法术数据!B:P,15,FALSE),"") | Z31: =IF(AB31="","",法术数据!AJ25) | AA31: =IFERROR(VLOOKUP(AB31,法术数据!B:P,15,FALSE),"") | AC31: =IF(AE31="","",法术数据!AV75) | AD31: =IFERROR(VLOOKUP(AE31,法术数据!B:P,15,FALSE),"") | AF31: =IF(AH31="","",法术数据!AJ25) | AG31: =IFERROR(VLOOKUP(AH31,法术数据!B:P,15,FALSE),"") | AI31: =IF(AK31="","",法术数据!AT75) | AJ31: =IFERROR(VLOOKUP(AK31,法术数据!B:P,15,FALSE),"")
T32: =IF(V32="","",法术数据!AJ26) | U32: =IFERROR(VLOOKUP(V32,法术数据!B:P,15,FALSE),"") | W32: =IF(Y32="","",法术数据!AJ76) | X32: =IFERROR(VLOOKUP(Y32,法术数据!B:P,15,FALSE),"") | Z32: =IF(AB32="","",法术数据!AJ26) | AA32: =IFERROR(VLOOKUP(AB32,法术数据!B:P,15,FALSE),"") | AC32: =IF(AE32="","",法术数据!AJ76) | AD32: =IFERROR(VLOOKUP(AE32,法术数据!B:P,15,FALSE),"") | AF32: =IF(AH32="","",法术数据!AJ26) | AG32: =IFERROR(VLOOKUP(AH32,法术数据!B:P,15,FALSE),"") | AI32: =IF(AK32="","",法术数据!AJ76) | AJ32: =IFERROR(VLOOKUP(AK32,法术数据!B:P,15,FALSE),"")
T33: =IF(V33="","",法术数据!AJ27) | U33: =IFERROR(VLOOKUP(V33,法术数据!B:P,15,FALSE),"") | W33: =IF(Y33="","",法术数据!AJ77) | X33: =IFERROR(VLOOKUP(Y33,法术数据!B:P,15,FALSE),"") | Z33: =IF(AB33="","",法术数据!AJ27) | AA33: =IFERROR(VLOOKUP(AB33,法术数据!B:P,15,FALSE),"") | AC33: =IF(AE33="","",法术数据!AV77) | AD33: =IFERROR(VLOOKUP(AE33,法术数据!B:P,15,FALSE),"") | AF33: =IF(AH33="","",法术数据!AJ27) | AG33: =IFERROR(VLOOKUP(AH33,法术数据!B:P,15,FALSE),"") | AI33: =IF(AK33="","",法术数据!AT77) | AJ33: =IFERROR(VLOOKUP(AK33,法术数据!B:P,15,FALSE),"")
T34: =IF(V34="","",法术数据!AJ28) | U34: =IFERROR(VLOOKUP(V34,法术数据!B:P,15,FALSE),"") | W34: =IF(Y34="","",法术数据!AJ78) | X34: =IFERROR(VLOOKUP(Y34,法术数据!B:P,15,FALSE),"") | Z34: =IF(AB34="","",法术数据!AJ28) | AA34: =IFERROR(VLOOKUP(AB34,法术数据!B:P,15,FALSE),"") | AC34: =IF(AE34="","",法术数据!AJ78) | AD34: =IFERROR(VLOOKUP(AE34,法术数据!B:P,15,FALSE),"") | AF34: =IF(AH34="","",法术数据!AJ28) | AG34: =IFERROR(VLOOKUP(AH34,法术数据!B:P,15,FALSE),"") | AI34: =IF(AK34="","",法术数据!AJ78) | AJ34: =IFERROR(VLOOKUP(AK34,法术数据!B:P,15,FALSE),"")
T35: =IF(V35="","",法术数据!AJ29) | U35: =IFERROR(VLOOKUP(V35,法术数据!B:P,15,FALSE),"") | W35: =IF(Y35="","",法术数据!AJ79) | X35: =IFERROR(VLOOKUP(Y35,法术数据!B:P,15,FALSE),"") | Z35: =IF(AB35="","",法术数据!AJ29) | AA35: =IFERROR(VLOOKUP(AB35,法术数据!B:P,15,FALSE),"") | AC35: =IF(AE35="","",法术数据!AV79) | AD35: =IFERROR(VLOOKUP(AE35,法术数据!B:P,15,FALSE),"") | AF35: =IF(AH35="","",法术数据!AJ29) | AG35: =IFERROR(VLOOKUP(AH35,法术数据!B:P,15,FALSE),"") | AI35: =IF(AK35="","",法术数据!AT79) | AJ35: =IFERROR(VLOOKUP(AK35,法术数据!B:P,15,FALSE),"")
T36: =IF(V36="","",法术数据!AJ30) | U36: =IFERROR(VLOOKUP(V36,法术数据!B:P,15,FALSE),"") | W36: =IF(Y36="","",法术数据!AJ80) | X36: =IFERROR(VLOOKUP(Y36,法术数据!B:P,15,FALSE),"") | Z36: =IF(AB36="","",法术数据!AJ30) | AA36: =IFERROR(VLOOKUP(AB36,法术数据!B:P,15,FALSE),"") | AC36: =IF(AE36="","",法术数据!AJ80) | AD36: =IFERROR(VLOOKUP(AE36,法术数据!B:P,15,FALSE),"") | AF36: =IF(AH36="","",法术数据!AJ30) | AG36: =IFERROR(VLOOKUP(AH36,法术数据!B:P,15,FALSE),"") | AI36: =IF(AK36="","",法术数据!AJ80) | AJ36: =IFERROR(VLOOKUP(AK36,法术数据!B:P,15,FALSE),"")
T37: =IF(V37="","",法术数据!AJ31) | U37: =IFERROR(VLOOKUP(V37,法术数据!B:P,15,FALSE),"") | W37: =IF(Y37="","",法术数据!AJ81) | X37: =IFERROR(VLOOKUP(Y37,法术数据!B:P,15,FALSE),"") | Z37: =IF(AB37="","",法术数据!AJ31) | AA37: =IFERROR(VLOOKUP(AB37,法术数据!B:P,15,FALSE),"") | AC37: =IF(AE37="","",法术数据!AV81) | AD37: =IFERROR(VLOOKUP(AE37,法术数据!B:P,15,FALSE),"") | AF37: =IF(AH37="","",法术数据!AJ31) | AG37: =IFERROR(VLOOKUP(AH37,法术数据!B:P,15,FALSE),"") | AI37: =IF(AK37="","",法术数据!AT81) | AJ37: =IFERROR(VLOOKUP(AK37,法术数据!B:P,15,FALSE),"")
T38: =IF(V38="","",法术数据!AJ32) | U38: =IFERROR(VLOOKUP(V38,法术数据!B:P,15,FALSE),"") | W38: =IF(Y38="","",法术数据!AJ82) | X38: =IFERROR(VLOOKUP(Y38,法术数据!B:P,15,FALSE),"") | Z38: =IF(AB38="","",法术数据!AJ32) | AA38: =IFERROR(VLOOKUP(AB38,法术数据!B:P,15,FALSE),"") | AC38: =IF(AE38="","",法术数据!AJ82) | AD38: =IFERROR(VLOOKUP(AE38,法术数据!B:P,15,FALSE),"") | AF38: =IF(AH38="","",法术数据!AJ32) | AG38: =IFERROR(VLOOKUP(AH38,法术数据!B:P,15,FALSE),"") | AI38: =IF(AK38="","",法术数据!AJ82) | AJ38: =IFERROR(VLOOKUP(AK38,法术数据!B:P,15,FALSE),"")
T39: =IF(V39="","",法术数据!AJ33) | U39: =IFERROR(VLOOKUP(V39,法术数据!B:P,15,FALSE),"") | W39: =IF(Y39="","",法术数据!AJ83) | X39: =IFERROR(VLOOKUP(Y39,法术数据!B:P,15,FALSE),"") | Z39: =IF(AB39="","",法术数据!AJ33) | AA39: =IFERROR(VLOOKUP(AB39,法术数据!B:P,15,FALSE),"") | AC39: =IF(AE39="","",法术数据!AV83) | AD39: =IFERROR(VLOOKUP(AE39,法术数据!B:P,15,FALSE),"") | AF39: =IF(AH39="","",法术数据!AJ33) | AG39: =IFERROR(VLOOKUP(AH39,法术数据!B:P,15,FALSE),"") | AI39: =IF(AK39="","",法术数据!AT83) | AJ39: =IFERROR(VLOOKUP(AK39,法术数据!B:P,15,FALSE),"")
T40: =IF(V40="","",法术数据!AJ34) | U40: =IFERROR(VLOOKUP(V40,法术数据!B:P,15,FALSE),"") | W40: =IF(Y40="","",法术数据!AJ84) | X40: =IFERROR(VLOOKUP(Y40,法术数据!B:P,15,FALSE),"") | Z40: =IF(AB40="","",法术数据!AJ34) | AA40: =IFERROR(VLOOKUP(AB40,法术数据!B:P,15,FALSE),"") | AC40: =IF(AE40="","",法术数据!AJ84) | AD40: =IFERROR(VLOOKUP(AE40,法术数据!B:P,15,FALSE),"") | AF40: =IF(AH40="","",法术数据!AJ34) | AG40: =IFERROR(VLOOKUP(AH40,法术数据!B:P,15,FALSE),"") | AI40: =IF(AK40="","",法术数据!AJ84) | AJ40: =IFERROR(VLOOKUP(AK40,法术数据!B:P,15,FALSE),"")
T41: =IF(V41="","",法术数据!AJ35) | U41: =IFERROR(VLOOKUP(V41,法术数据!B:P,15,FALSE),"") | W41: =IF(Y41="","",法术数据!AJ85) | X41: =IFERROR(VLOOKUP(Y41,法术数据!B:P,15,FALSE),"") | Z41: =IF(AB41="","",法术数据!AJ35) | AA41: =IFERROR(VLOOKUP(AB41,法术数据!B:P,15,FALSE),"") | AC41: =IF(AE41="","",法术数据!AV85) | AD41: =IFERROR(VLOOKUP(AE41,法术数据!B:P,15,FALSE),"") | AF41: =IF(AH41="","",法术数据!AJ35) | AG41: =IFERROR(VLOOKUP(AH41,法术数据!B:P,15,FALSE),"") | AI41: =IF(AK41="","",法术数据!AT85) | AJ41: =IFERROR(VLOOKUP(AK41,法术数据!B:P,15,FALSE),"")
...

Sheet 综合数据
A1: 版本控制 | C1: 等级 | F1: 生命值计算 | G1: 经验条 | H1: =主要!Y3 -> 1 | I1: 属性 | J1: FALSE | K1: FALSE | L1: FALSE | M1: FALSE | N1: FALSE | O1: FALSE | P1: 技能 | S1: 种类 | T1: 购点计算
A2: PHB | B2: TRUE | C2: 等级 | D2: 经验 | E2: 熟练 | F2: =IF(种族数据!V4=种族数据!B2,1,0)+IF(种族数据!V4=种族数据!K5,2,0)+IF(COUNTIF(专长数据!E2:E7,专长数据!A36),2,0) -> 0 | G2: =主要!R3 -> 0 | H2: =IFERROR(IF(H1=20,IF(H1=20,MOD((G2-D22),30000)/30000),(G2-VLOOKUP(H1,C3:D21,2,0))/((VLOOKUP(H1+1,C3:D21,2,0)-VLOOKUP(H1,C3:D21,2,0)))),0) -> 0 | I2: 1 | J2: 你还有呼吸的力气 | K2: 一动不动 | L2: 应该还算活着 | M2: 蚂蚁的智力都不可能是1 | N2: 你是怎么活到现在的 | O2: 用脸就能恐惧敌人 | P2: 运动 | Q2: =主要!I39 -> -1 | R2: FALSE | S2: 异怪 | T2: 8 | U2: 0
A3: DMG | B3: TRUE | C3: 1 | D3: 0 | E3: 2 | F3: =IF(主要!AW4="",0,主要!AW4+主要!$R$16+F2) -> 9 | G3: 0 | H3: =D4-G3 -> 300 | I3: 2 | J3: 连一枚金币都拿不起来 | K3: 残疾人士 | L3: 固有Buff：病弱 | M3: 连说话都困难 | N3: 迷惘的人啊 | O3: 你出生的时候居然没被掐死 | P3: 体操 | Q3: =主要!I41 -> 4 | R3: FALSE | S3: 野兽 | T3: 9 | U3: 1
A4: MM | B4: TRUE | C4: 2 | D4: 300 | E4: 2 | F4: =IF(主要!AY4="",0,MAX(主要!AY4+主要!$R$16,1)+F2) -> 0 | G4: =D4+1 -> 301 | H4: =D5-G4 -> 599 | I4: 3 | J4: 鸡的力量都比你强 | K4: 无法行动自如 | L4: 突然挂掉都不是奇怪的事情 | M4: 目不识丁 | N4: 上错过厕所 | O4: 路边的狗可能会冲过来咬你 | P4: 巧手 | Q4: =主要!I42 -> 4 | R4: FALSE | S4: 天界生物 | T4: 10 | U4: 2
A5: SCAG | B5: TRUE | C5: 3 | D5: 900 | E5: 2 | F5: =IF(主要!BA4="",0,MAX(主要!BA4+主要!$R$16,1)+F2) -> 0 | G5: =D5+1 -> 901 | H5: =D6-G5 -> 1799 | I5: 4 | J5: 手无抓鸡之力 | K5: 腿脚不灵活 | L5: 您的每一天都是上天的恩赐 | M5: 你能看得懂这行字？ | N5: 经常迷路 | O5: 容易被排斥 | P5: 隐匿 | Q5: =主要!I43 -> 6 | R5: FALSE | S5: 构装生物 | T5: 11 | U5: 3
A6: VGM | B6: TRUE | C6: 4 | D6: 2700 | E6: 2 | F6: =IF(主要!BC4="",0,MAX(主要!BC4+主要!$R$16,1)+F2) -> 0 | G6: =D6+1 -> 2701 | H6: =D7-G6 -> 3799 | I6: 5 | J6: 恭喜你超越了鸡的力量 | K6: 平地摔是你的家常便饭 | L6: 常年病痛缠身 | M6: 阿库娅与你同在 | N6: 在楼房里面找不到房间 | O6: 可能会被人刁难 | P6: 奥秘 | Q6: =主要!I45 -> 4 | R6: FALSE | S6: 龙类 | T6: 12 | U6: 4
A7: XGE | B7: TRUE | C7: 5 | D7: 6500 | E7: 3 | F7: =IF(主要!BE4="",0,MAX(主要!BE4+主要!$R$16,1)+F2) -> 0 | G7: =D7+1 -> 6501 | H7: =D8-G7 -> 7499 | I7: 6 | J7: 拿多点东西都气喘吁吁 | K7: 经常莫名其妙的撞上什么 | L7: 经常需要躺下休息 | M7: 学不下什么东西 | N7: 东西放在眼前就是找不到 | O7: 可能会受到种种审视 | P7: 历史 | Q7: =主要!I46 -> 2 | R7: FALSE | S7: 元素生物 | T7: 13 | U7: 5
A8: MTF | B8: TRUE | C8: 6 | D8: 14000 | E8: 3 | F8: =IF(主要!BG4="",0,MAX(主要!BG4+主要!$R$16,1)+F2) -> 0 | G8: =D8+1 -> 14001 | H8: =D9-G8 -> 8999 | I8: 7 | J8: 穿脱衣服都有些吃力 | K8: 走在平地上都会摔倒 | L8: 可能有贫血什么的 | M8: 没有受过太多的教育 | N8: 偶尔会犯迷糊 | O8: 所有的人都觉得可以轻而易举地说服你 | P8: 调查 | Q8: =主要!I47 -> 6 | R8: FALSE | S8: 精类 | T8: 14 | U8: 7
A9: GTR | B9: TRUE | C9: 7 | D9: 23000 | E9: 3 | F9: =IF(主要!BI4="",0,MAX(主要!BI4+主要!$R$16,1)+F2) -> 0 | G9: =D9+1 -> 23001 | H9: =D10-G9 -> 10999 | I9: 8 | J9: 你揍人就像在给对方按摩 | K9: 不上不下真尴尬 | L9: 健康状况堪忧 | M9: 你可能会怀疑你是不是健忘 | N9: 关键时刻掉链子 | O9: 你的说服力还是可以的 | P9: 自然 | Q9: =主要!I48 -> 4 | R9: FALSE | S9: 邪魔 | T9: 15 | U9: 9
A10: ERLW | B10: TRUE | C10: 8 | D10: 34000 | E10: 3 | F10: =IF(主要!BK4="",0,MAX(主要!BK4+主要!$R$16,1)+F2) -> 0 | G10: =D10+1 -> 34001 | H10: =D11-G10 -> 13999 | I10: 9 | J10: 比正常人稍微差一点 | K10: 比正常人稍微差一点 | L10: 比正常人稍微差一点 | M10: 思维比别人慢一拍 | N10: 比正常人稍微差一点 | O10: 比正常人稍微差一点 | P10: 宗教 | Q10: =主要!I49 -> 4 | R10: FALSE | S10: 巨人
A11: EGtW | B11: TRUE | C11: 9 | D11: 48000 | E11: 4 | F11: =IF(主要!BM4="",0,MAX(主要!BM4+主要!$R$16,1)+F2) -> 0 | G11: =D11+1 -> 48001 | H11: =D12-G11 -> 15999 | I11: 10 | J11: 有正常人的力量 | K11: 普通人的水准 | L11: 正常人的体质 | M11: 正常人的智力 | N11: 你醒啦，你很正常 | O11: 讨价还价的能力不错 | P11: 驯兽 | Q11: =主要!I51 -> 4 | R11: FALSE | S11: 类人生物
A12: Acq Inc. | B12: TRUE | C12: 10 | D12: 64000 | E12: 4 | F12: =IF(主要!BO4="",0,MAX(主要!BO4+主要!$R$16,1)+F2) -> 0 | G12: =D12+1 -> 64001 | H12: =D13-G12 -> 20999 | I12: 11 | J12: 在这个档次，做到欺软怕硬是没有问题的 | K12: 可以徒手抓住苍蝇 | L12: 疾病对于您来说，应该是偶发事故 | M12: 可以耍耍小聪明 | N12: 找东西的时候方便一些 | O12: 可以很容易地虎躯一震 | P12: 洞悉 | Q12: =主要!I52 -> 6 | R12: FALSE | S12: 怪兽
A13: MOT | B13: TRUE | C13: 11 | D13: 85000 | E13: 4 | F13: =IF(主要!AW7="",0,MAX(主要!AW7+主要!$R$16,1)+F2) -> 0 | G13: =D13+1 -> 85001 | H13: =D14-G13 -> 14999 | I13: 12 | J13: 经常锻炼的人能够达到的水平，可以很轻松地连续做上50个俯卧撑 | K13: 可以用筷子夹住苍蝇 | L13: 基本上没有吃过什么药，不是说不得病，但基本上抗一抗就过去了 | M13: 人才啊 | N13: 可以注意到别人注意不到的细节 | O13: 勉勉强强可以放出一丝王霸之气 | P13: 医药 | Q13: =主要!I53 -> 6 | R13: FALSE | S13: 泥怪
A14: TCE | B14: TRUE | C14: 12 | D14: 100000 | E14: 4 | F14: =IF(主要!AY7="",0,MAX(主要!AY7+主要!$R$16,1)+F2) -> 0 | G14: =D14+1 -> 100001 | H14: =D15-G14 -> 19999 | I14: 13 | J14: 一拳一个小朋友 | K14: 很不错的反应能力，可以在旋转的硬币落下的一瞬间看出是哪面落地 | L14: 一般的磕磕碰碰都不放在眼里 | M14: 可以很轻松地取得别人要刻苦努力才能得到的成绩 | N14: 可以推断出一些别人不知道的东西 | O14: 人们更容易接受你的意见 | P14: 察觉 | Q14: =主要!I54 -> 6 | R14: FALSE | S14: 植物
A15: VRGR | B15: TRUE | C15: 13 | D15: 120000 | E15: 5 | F15: =IF(主要!BA7="",0,MAX(主要!BA7+主要!$R$16,1)+F2) -> 0 | G15: =D15+1 -> 120001 | H15: =D16-G15 -> 19999 | I15: 14 | J15: =J14 -> 一拳一个小朋友 | K15: =K14 -> 很不错的反应能力，可以在旋转的硬币落下的一瞬间看出是哪面落地 | L15: =L14 -> 一般的磕磕碰碰都不放在眼里 | M15: =M14 -> 可以很轻松地取得别人要刻苦努力才能得到的成绩 | N15: =N14 -> 可以推断出一些别人不知道的东西 | O15: =O14 -> 人们更容易接受你的意见 | P15: 求生 | Q15: =主要!I55 -> 4 | R15: FALSE | S15: 不死生物
A16: FTD | B16: TRUE | C16: 14 | D16: 140000 | E16: 5 | F16: =IF(主要!BC7="",0,MAX(主要!BC7+主要!$R$16,1)+F2) -> 0 | G16: =D16+1 -> 140001 | H16: =D17-G16 -> 24999 | I16: 15 | J16: =J17 -> 超乎常人的力度 | K16: =K17 -> 左右横跳 | L16: =L17 -> 你从来就不知道什么叫生病 | M16: =M17 -> 就是个天才 | N16: =N17 -> 身边的一切风吹草动都逃不出您的敏锐的目光 | O16: =O17 -> 您不经意间的一举一动都有可能吸引着其他人 | P16: 欺瞒 | Q16: =主要!I57 -> 0 | R16: FALSE
A17: SCC | B17: TRUE | C17: 15 | D17: 165000 | E17: 5 | F17: =IF(主要!BE7="",0,MAX(主要!BE7+主要!$R$16,1)+F2) -> 0 | G17: =D17+1 -> 165001 | H17: =D18-G17 -> 29999 | I17: 16 | J17: 超乎常人的力度 | K17: 左右横跳 | L17: 你从来就不知道什么叫生病 | M17: 就是个天才 | N17: 身边的一切风吹草动都逃不出您的敏锐的目光 | O17: 您不经意间的一举一动都有可能吸引着其他人 | P17: 威吓 | Q17: =主要!I58 -> 0 | R17: FALSE
A18: MotM | B18: TRUE | C18: 16 | D18: 195000 | E18: 5 | F18: =IF(主要!BG7="",0,MAX(主要!BG7+主要!$R$16,1)+F2) -> 0 | G18: =D18+1 -> 195001 | H18: =D19-G18 -> 29999 | I18: 17 | J18: =J17 -> 超乎常人的力度 | K18: =K17 -> 左右横跳 | L18: =L17 -> 你从来就不知道什么叫生病 | M18: =M17 -> 就是个天才 | N18: =N17 -> 身边的一切风吹草动都逃不出您的敏锐的目光 | O18: =O17 -> 您不经意间的一举一动都有可能吸引着其他人 | P18: 表演 | Q18: =主要!I59 -> 0 | R18: FALSE
A19: MOD | B19: FALSE | C19: 17 | D19: 225000 | E19: 6 | F19: =IF(主要!BI7="",0,MAX(主要!BI7+主要!$R$16,1)+F2) -> 0 | G19: =D19+1 -> 225001 | H19: =D20-G19 -> 39999 | I19: 18 | J19: 达到人类极限力量 | K19: 超越人类的敏捷 | L19: 生命力旺盛，被人打趴数次还可以站起来继续的那种 | M19: 睿智的目光 | N19: 这个世界上的一切联系都可以被您所感知 | O19: 请注意你的其他属性，因为你很容易被犯罪 | P19: 游说 | Q19: =主要!I60 -> 0 | R19: FALSE
C20: 18 | D20: 265000 | E20: 6 | F20: =IF(主要!BK7="",0,MAX(主要!BK7+主要!$R$16,1)+F2) -> 0 | G20: =D20+1 -> 265001 | H20: =D21-G20 -> 39999 | I20: 19 | J20: 超越人类极限的力量 | K20: 你跑步的样子像香港记者 | L20: 天生的肉盾 | M20: 超凡的智慧 | N20: 你开始注意到一些本来不该是人类所注意的东西了 | O20: 红颜祸水指的就是你 | P20: 货币换算 | Q20: 弹药计重 | R20: TRUE
C21: 19 | D21: 305000 | E21: 6 | F21: =IF(主要!BM7="",0,MAX(主要!BM7+主要!$R$16,1)+F2) -> 0 | G21: =D21+1 -> 305001 | H21: =D22-G21 -> 49999 | I21: 20 | J21: 熊的力量！ | K21: 无与伦比的运动神经 | L21: 或许有复数血条 | M21: 你可以改变世界 | N21: 所有的谎言在你面前无所遁形 | O21: 沉鱼落雁，闭月羞花 | P21: =IFERROR(IF(主要!H62=P22,主要!B62/100,IF(主要!H62=P23,主要!B62/10,IF(主要!H62=P24,主要!B62/2,IF(主要!H62=P25,主要!B62,IF(主要!H62=P26,主要!B62*10,""))))),"") -> 0 | Q21: 货币计重 | R21: TRUE
C22: 20 | D22: 355000 | E22: 6 | F22: =IF(主要!BO7="",0,MAX(主要!BO7+主要!$R$16,1)+F2) -> 0 | I22: 21 | J22: 怪物之力 | K22: 跑得比香港记者还快 | L22: 大概只有天灾才杀死这种人 | M22: 或许是参透法则之人 | N22: 路过坟墓你就能看见鬼魂，经过战场你就能听见哀号 | O22: 您的敌人也可能会倾向于你 | P22: 铜币CP
I23: 22 | J23: 吃饭的时候经常不小心捏碎十几个盘子 | K23: 只要你想要，世界上没什么你弄不到东西 | L23: 被杀不一定会死 | M23: 用睿智这个词来形容你都已经是一种侮辱了 | N23: 敌人的隐形和变形对你来说毫无意义 | O23: 你很少动刀动枪，因为只要有你的存在就能化解绝大多数的纷争 | P23: 银币SP
I24: 23 | J24: 经常不小心将别人摸成骨折，当地的骨科医生都很喜欢你 | K24: 几乎没有东西有足够的速度能伤害到你 | L24: 最受欢迎的肉盾 | M24: 你一眼就能看清事物的本质，再没有任何事物能够引起你的好奇 | N24: 任何生物在你眼中他的一生命运都历历在目，任何非生物的历史你也一目了然 | O24: 只有意志最坚定的人才能直视你 | P24: 银金币EP
I25: 24 | J25: 你付账的时候从口袋里掏出来的，往往不是金币而是被巨大的力量捏成一坨的金块 | K25: 战斗的时候，敌人最头痛的就是你，因为他根本砍不到你 | L25: 强壮的体质使你在冒险团队中所向无敌 | M25: 世间的一切在你眼中都索然无味 | N25: 世界上所有的神祗都在要求你做他们的使徒 | O25: 你的一个眼神、一个动作，都可能轻易的左右其他人的思想，决定国家的存亡 | P25: 金币GP
I26: 25 | J26: 因为你的存在，你所居住的小镇已经很多年没有买过起重机了 | K26: 你从别人身边走过，别人会以为只是一阵风吹过 | L26: 传奇肉盾 | M26: 完全可以去客串半神巫妖 | N26: 你能够直接倾听神祗的话语与神交流，你就是真正的神使 | O26: 天上的众神为了争夺你打的不可开交，深渊中的恶魔因为你的存在而不愿破坏世界 | P26: 铂金币PP

Sheet 种族数据
B1: 亚种 | C1: PHB | D1: SCAG | E1: VGM | F1: MTF | G1: GTR | H1: ERLW | I1: EGtW | J1: AcqInc. | K1: MOT | L1: VRGR | M1: FTD | N1: SCC | O1: MotM | P1: MOD | R1: 体型 | S1: 种族备选 | T1: 亚种选项 | V1: 种族特性 | Z1: 待选特性 | AB1: 已选特性 | AE1: 种族 | AF1: 行 | AG1: 最小列 | AH1: 最大列 | AI1: 通用特性 | AJ1: 属性值加成 | AK1: 体型 | AL1: 速度 | AM1: 语言 | AN1: 阿斯莫向导特质 | AO1: 阿斯莫天界特性 | AP1: 蜥蜴人怪癖 | AQ1: 斑猫人追求 | AR1: 斑猫人怪癖 | AS1: 梭螺鱼人怪癖 | AT1: 精灵饰品 | AU1: 精灵冒险动机 | AV1: 卓尔冒险动机 | AW1: 卓尔家族专业 | AX1: 雅灵联系季节 | AY1: 秋季人格特点 | AZ1: 秋季缺陷 | BA1: 冬季人格特点 | BB1: 冬季缺陷 | BC1: 春季人格特点 | BD1: 春季缺陷 | BE1: 夏季人格特点 | BF1: 夏季缺陷 | BG1: 离梦人癖好 | BH1: 兽人外出理由 | BI1: 机关人怪癖 | BJ1: 矮人离开原因 | BK1: 侏儒的计画 | BL1: 半精灵起源 | BM1: 半身人怪癖 | BN1: 人类起源 | BO1: 半血裔饥渴 | BP1: 半血裔起源 | BQ1: 巫咒之子起源 | BR1: 重生者遗失的记忆 | BS1: 仙灵精类特征 | BT1: 化兽者兽化人先祖
A2: 矮人 | B2: 丘陵矮人 | C2: 山地矮人 | D2: =IF(OR(综合数据!B8=TRUE,综合数据!B18=TRUE),"灰矮人","") -> 灰矮人 | E2: =IF(综合数据!B10=TRUE,"警戒龙纹","") -> 警戒龙纹 | F2: ="" | G2: ="" | H2: ="" | I2: ="" | J2: ="" | K2: ="" | L2: ="" | M2: ="" | ... O2: ="" | R2: 微型 | S2: {=INDEX(A:A,SMALL(IF($A$2:$A$45<>"",ROW($2:$45),46),ROW(A1)))&""} -> 矮人 | T2: =VLOOKUP(V3,AE2:AF125,2,0) -> #N/A | U2: {=INDEX(T:T,SMALL(IF($T$3:$T$15<>"",ROW($3:$15),16),ROW(T1)))&""} -> #N/A | V2: =IF(主要!Y3="",0,主要!Y3) -> 1 | W2: 行 | X2: 最小列 | Y2: 最大列 | Z2: =IFERROR(IF(COUNTIF($AB$2:$AB$15,$W6),"",W6),"") | AA2: {=INDEX(Z:Z,SMALL(IF($Z$2:$Z$16<>"",ROW($2:$16),17),ROW(Z1)))&""} -> 语言 | AB2: =IF(主要!$Z84="",0,主要!$Z84) -> 属性值加成 | AC2: =IFERROR(VLOOKUP($AB2,$W$6:$X$27,2,0),"") | AD2: =IF($AB2=0,"",COUNTIF($AB$2:$AB$15,$AB2)) -> 1 | AE2: 矮人 | AF2: 1 | AG2: 1 | AH2: 5 | AI2: 丘陵矮人 | AJ2: 体质+2，感知+1 | AK2: 中型 | AL2: 基础步行速度为25尺，你的速度不会因穿着重甲而减慢 | AM2: 和矮人语 | AN2: 书生气的，教条主义的 | AO2: 锈蚀金属色、白色或木炭色的雀斑 | AP2: 你讨厌浪费，而且没有理由不清理吃光死掉的敌人。手指美味又方便！ | AQ2: 一位神祇或者位面存在 | AR2: 你想念你的热带家乡，对寒冷的天气抱怨不休，哪怕是在夏天。 | AS2: 你所说的话即是需要服从的命令。 | AT2: 一个小笔记本，任何写在上面的东西都会在一小时内消失。 | AU2: 你相信让精灵与科瑞隆重新团聚的秘密在世界上的某处而不在精灵社区之中，而你下定决心要找到这个秘密。 | AV2: 你打听到了你的家族中一位成员试图毒杀你，因而你从幽暗地域逃脱以保命。你在闯出足以让你身边有着一群忠诚的佣兵护卫前不会回去。 | AW2: 精金武器 | AX2: 秋是和平与善意的季节，众生分享着夏季的丰收。 | AY2: 如果有人需要你的帮助，你会毫无保留地伸出援手。 | AZ2: 你不暇思索地相信别人。 | BA2: 最坏的情况总是最可能发生的。 | BB2: 万物终有一死。为何还要麻烦地建造那些长存的事物呢？ | BC2: 每一天都是你生命中最美好的一天。 | BD2: 你常常酗酒。 | BE2: 你相信单刀直入是解决问题的最佳方式。 | BF2: 你很顽固。“改变”这种事让别人去做吧。 | BG2: 你试图了解敌人的动机和感受 | BH2: 你和护门者有联系，而你正要执行在阴影湿地外对抗一个与恶魔有关的威胁的委托。 | BI2: 你大声分析遇见的每个人可能会带来的潜在威胁。 | BJ2: 与敌对氏族之间的宿怨已经失控，最好是在事情平静下来的时候离开几十年。 | BK2: 你的家人正在研究一种新的元素绑定形式，但是他们需要很多凯博尔龙晶。 | BL2: 你是一个主要城市的科拉瓦社区的关键人物，主持团结餐会，并与城市中每一个半精灵保持联系。 | BM2: 你常常惊讶於五国人民认为理所当然的事情。 | BN2: 来自安黛尔的贫穷法师，努力证明你和其他安黛尔法师一样聪明 | BO2: 饥渴 | BP2: 你是吸血鬼暴君祖先的转世。 | BQ2: 想要有个孩子，你的父母和鬼婆进行了交易，而你就是那场交易的产物。 | BR2: 你回想起身体承受的巨大痛苦，你身上与之相关的伤痕或印记是什么样的？ | BS2: 你的翅膀如同鸟类的翅膀。 | BT2: 熊人
A3: 精灵 | B3: 高等精灵 | C3: 木精灵 | D3: 黑暗精灵 | E3: =IF(OR(综合数据!B8=TRUE,综合数据!B18=TRUE),"雅灵","") -> 雅灵 | F3: =IF(OR(综合数据!B8=TRUE,综合数据!B18=TRUE),"海精灵","") -> 海精灵 | G3: =IF(OR(综合数据!B8=TRUE,综合数据!B18=TRUE),"影灵","") -> 影灵 | H3: =IF(综合数据!B10=TRUE,"阴影龙纹","") -> 阴影龙纹 | I3: =IF(综合数据!B11=TRUE,"苍白精灵","") -> 苍白精灵 | J3: ="" | K3: ="" | L3: ="" | M3: ="" | N3: ="" | O3: ="" | R3: 小型 | S3: {=INDEX(A:A,SMALL(IF($A$2:$A$45<>"",ROW($2:$45),46),ROW(A2)))&""} -> 精灵 | T3: =INDEX($B$2:$K$45,$T$2,1) -> #N/A | U3: {=INDEX(T:T,SMALL(IF($T$3:$T$15<>"",ROW($3:$15),16),ROW(T2)))&""} -> #N/A | V3: =IF(主要!$D6="",0,主要!$D6) -> 拉文克劳 | W3: =IF(COUNTIF(T13:T15,V4)=0,VLOOKUP(V3,AE:AF,2,0)*2,VLOOKUP(V4,AE:AF,2,0)*2) -> #N/A | Y3: =IF(COUNTIF(T13:T15,V4)=0,VLOOKUP(V3,AE:AH,4,0),VLOOKUP(V4,AE:AH,4,0)) -> #N/A | Z3: =IFERROR(IF(COUNTIF($AB$2:$AB$15,$W7),"",W7),"") | AA3: {=INDEX(Z:Z,SMALL(IF($Z$2:$Z$16<>"",ROW($2:$16),17),ROW(Z2)))&""} | AB3: =IF(主要!$Z85="",0,主要!$Z85) -> 速度 | AC3: =IFERROR(VLOOKUP($AB3,$W$6:$X$27,2,0),"") | AD3: =IF($AB3=0,"",COUNTIF($AB$2:$AB$15,$AB3)) -> 1 | AE3: 丘陵矮人 | AG3: 6 | AH3: 6 | AI3: 山地矮人 | AJ3: 体质+2，力量+2 | AK3: =AK$2 -> 中型 | AL3: =AL$2 -> 基础步行速度为25尺，你的速度不会因穿着重甲而减慢 | AM3: =AM$2 -> 和矮人语 | AN3: 富有同情心的，给人以希望的 | AO3: 金属般的、发光的或黑暗的眼睛 | AP3: 你把大部分身体泡在水里的时候睡得最香。 | AQ3: 一只怪物 | AR3: 除非绝对必要，你从不穿同样的衣服两次。 | AS3: 你动不动就夸耀你的文明的伟大。 | AT3: 一个用象牙与黄金制成的水晶透镜，透过它，任何东西看起来都会变得色彩缤纷 | AU3: 你的同胞血亲被一个疯狂的怪物杀死了，你在击败它、杀死它前绝不停息。 | AV3: 你因为试图毒杀你有权有势的竞争对手而被奴役作为惩罚，但你逃脱了奴役并逃至地表。若你回归，你将被再次奴役。 | AW3: 暗杀 | AX3: 冬是冥想与悲伤的季节，生机勃勃的世界蛰伏了。 | AY3: 你会分享你的所有，而不考虑你自己的需求。 | AZ3: 你倾尽所有给予别人，却连必要的补给都不留给自己。 | BA3: 你会把你的所有都保存起来。今天挨饿明天饱餐总比反过来的情况好。 | BB3: 你不看重任何事，所以你允许让人引导你的行动。 | BC3: 你做任何事都饱含热情，即使是最乏味的家务事。 | BD3: 苦工是苦力的活。安逸是你的生活。 | BE3: 压倒性的力量可以解决任何事。问题越困难，就该用更大的力量。 | BF3: 最好的选择是一个人出手迅速、出人意料并且势不可挡。 | BG3: 你喜欢通过心灵感应而不是大声说话来交流 | BH3: 萨拉释克家族从沼泽中中招募你，在终末之战中充当雇佣军。 | BI3: 你经常误解情绪表现。 | BJ3: 你来自一个大家庭，没有位置让你展露光芒，所以你希望让自己在更广阔的世界出名。 | BK3: 你有一个匿名联系人通过短讯术给你发送任务。如果你按照要求去做，你会得到丰厚的回报。 | BL3: 你在一个由人类主宰的小镇上长大。你不认识任何其他半精灵，你尽了最大努力去融入他们。 | BM3: 你模仿一种恐龙的行为。 | BN3: 一个来自布鲁兰的街头盗贼，只想永远逃离萨恩的喧嚣 | BO3: 血液 | BP3: 你与一位具有掠夺性的神祇，邪魔，精类或灵魂缔结了契约，共享它们的饥渴。 | BQ3: 精类绑架者把你和你父母的孩子进行了替换。 | BR3: 回忆使你热泪盈眶。是苦涩的回忆还是甜美的回忆？现在回想起来你的感受是否还如当初一样？ | BS3: 你的皮肤闪闪发光，五彩缤纷。 | BT3: 野猪人
A4: 半身人 | B4: 轻足半身人 | C4: 敦实半身人 | D4: =IF(综合数据!B5=TRUE,"鬼智半身人","") -> 鬼智半身人 | E4: =IF(综合数据!B10=TRUE,"医疗龙纹","") -> 医疗龙纹 | F4: =IF(综合数据!B10=TRUE,"招待龙纹","") -> 招待龙纹 | G4: =IF(综合数据!B11=TRUE,"莲源半身人","") -> 莲源半身人 | H4: ="" | I4: ="" | J4: ="" | K4: ="" | L4: ="" | M4: ="" | N4: ="" | O4: ="" | R4: 中型 | S4: {=INDEX(A:A,SMALL(IF($A$2:$A$45<>"",ROW($2:$45),46),ROW(A3)))&""} -> 半身人 | T4: =INDEX($B$2:$K$45,$T$2,2) -> #N/A | U4: {=INDEX(T:T,SMALL(IF($T$3:$T$15<>"",ROW($3:$15),16),ROW(T3)))&""} -> #N/A | V4: =IF(主要!$D7="",0,主要!$D7) -> 0 | W4: =W3-1 -> #N/A | X4: =IF(COUNTIF(T13:T15,V4)=0,VLOOKUP(V4,AE:AG,3,0),0/0) -> #N/A | Y4: =VLOOKUP(V4,AE:AH,4,0) -> #N/A | Z4: =IFERROR(IF(COUNTIF($AB$2:$AB$15,$W8),"",W8),"") | AA4: {=INDEX(Z:Z,SMALL(IF($Z$2:$Z$16<>"",ROW($2:$16),17),ROW(Z3)))&""} | AB4: =IF(主要!$Z86="",0,主要!$Z86) -> 体型 | AC4: =IFERROR(VLOOKUP($AB4,$W$6:$X$27,2,0),"") | AD4: =IF($AB4=0,"",COUNTIF($AB$2:$AB$15,$AB4)) -> 1 | AE4: 山地矮人 | AG4: 7 | AH4: 7 | AI4: 灰矮人 | AJ4: 自选两项属性分别+2/+1或自选三项属性+1 | AK4: =AK$2 -> 中型 | AL4: 基础步行速度为30尺 | AM4: ，以及任意一门自选语言 | AN4: 实际主义的，使人轻松的 | AO4: 多种颜色层叠的头发 | AP4: 金钱对你来说毫无意义。 | AQ4: 一个失落的文明 | AR4: 你有轻微的恐水症，讨厌被水弄湿。 | AS4: 你习得了过时版本的通用语，并将“汝”用在你的话中。 | AT4: 一个核桃大小的金色金字塔，其上刻有精灵符文 | AU4: 一只渡鸦带来了你的一位需要援助的老友的密信，但密信中关于你这位老友的位置信息相当模糊。你正尝试花上数年时间来追踪、拯救你的老友。 | AV4: 你是一位罗丝高阶女祭司的情人，你以此作为你地位的保证。当她厌倦了你时，失去地位对你而言是个耻辱，所以你离开了。 | AW4: 基于魔法控制的巨蜘蛛养殖 | AX4: 春是快乐与庆祝的季节，欢喜随冬之悲伤的离去而来。 | AY4: 这里没有饱腹的简餐，只有奢华的盛宴。 | AZ4: 每个人都是你的朋友或者潜在的朋友。 | BA4: 生活充满了危险，但你已做好准备。 | BB4: 你的需求是第一位。在寒冬，每个人都必须照顾好自己。 | BC4: 你热爱音乐与歌唱。如果没人能为你写歌，你会为自己谱曲。 | BD4: 美人能将你轻易俘虏，但你的热情来得快去得也快。 | BE4: 你站得强健而挺拔，以便让他人能依靠你。 | BF4: 比起动口，你会先动手。 | BG4: 你有一种保护无辜者的强烈冲动 | BH4: 你是一个孤狼猎手，但你已经决定寻找进一步的机会或是湿地外世界的真正挑战。 | BI4: 你极力保护自己的朋友。 | BJ4: 你的氏族已经为你的婚姻和未来做了安排，你已经决定在安定下来之前进行一些冒险活动。 | BK4: 你继承了夸巴拉的一块地。如果你在一年内不访问，你将失去所有权。 | BL4: 你住在埃鲁登原野的一个小科拉瓦社区，你试图成为东部人类农民和西部德鲁伊教和野人之间的桥梁。 | BM4: 你非常好奇，总是在寻找新的经历。 | BN4: 一名流离失所的赛尔战士，哀伤咏叹期间在赛尔外参与了战争，现在被困在了没有家的地方 | BO4: 生肉 | BP4: 你从一位吸血鬼的攻击中幸存了下来，但是也被永远的改变了。 | BQ4: 一个鬼婆集会失去了一名成员。你被创造出来填补缺失的空位。 | BR4: 你回想起孩童时期的事情。那时候的什么事件或人物至今仍在影响着你？ | BS4: 你有着特别大的耳朵。 | BT4: 鼠人
A5: 人类 | B5: 人类变体 | C5: =IF(综合数据!B10=TRUE,"探索龙纹","") -> 探索龙纹 | D5: =IF(综合数据!B10=TRUE,"畜牧龙纹","") -> 畜牧龙纹 | E5: =IF(综合数据!B10=TRUE,"创造龙纹","") -> 创造龙纹 | F5: =IF(综合数据!B10=TRUE,"通行龙纹","") -> 通行龙纹 | G5: =IF(综合数据!B10=TRUE,"守护龙纹","") -> 守护龙纹 | H5: =IF(综合数据!B19=TRUE,"加渥尼","") | I5: =IF(综合数据!B19=TRUE,"凯锡革","") | J5: =IF(综合数据!B19=TRUE,"涅非利亚","") | K5: =IF(综合数据!B19=TRUE,"史顿襄","") | L5: ="" | M5: ="" | N5: ="" | O5: ="" | R5: 大型 | S5: {=INDEX(A:A,SMALL(IF($A$2:$A$45<>"",ROW($2:$45),46),ROW(A4)))&""} -> 人类 | T5: =INDEX($B$2:$K$45,$T$2,3) -> #N/A | U5: {=INDEX(T:T,SMALL(IF($T$3:$T$15<>"",ROW($3:$15),16),ROW(T4)))&""} -> #N/A | V5: 序号 | W5: 名称 | X5: 描述 | Y5: 增值 | Z5: =IFERROR(IF(COUNTIF($AB$2:$AB$15,$W9),"",W9),"") -> 语言 | AA5: {=INDEX(Z:Z,SMALL(IF($Z$2:$Z$16<>"",ROW($2:$16),17),ROW(Z4)))&""} | AB5: =IF(主要!$Z87="",0,主要!$Z87) -> 深厚学识 | AC5: =IFERROR(VLOOKUP($AB5,$W$6:$X$27,2,0),"") | AD5: =IF($AB5=0,"",COUNTIF($AB$2:$AB$15,$AB5)) -> 1 | AE5: 灰矮人 | AG5: 8 | AH5: =IF(V2<3,9,10) -> 9 | AI5: 警戒龙纹 | AJ5: 体质+2，智力+1 | AK5: =AK$2 -> 中型 | AL5: =AL$2 -> 基础步行速度为25尺，你的速度不会因穿着重甲而减慢 | AM5: =AM$2 -> 和矮人语 | AN5: 狂热的，报复心猛烈的 | AO5: 你的影子有不寻常的色调 | AP5: 你认为世界上只有两种人：蜥蜴人和食用肉。 | AQ5: 一名法师的秘密 | AR5: 你的尾巴总是背叛你内心的想法。 | AS5: 你认为人们都在告诉你当地风俗习惯和期望的真相。 | AT5: 一个蝴蝶形的，用搪瓷制成的斗篷针；当你取下它时，它会变成一只真正的蝴蝶，在你准备把它戴回去前又会再变成针。 | AU5: 一个美丽的精灵赢得了，又打碎了你的心。如果你通过冒险挣得了足够的金钱与荣誉，你或许可以让你的爱人回心转意。 | AV5: 你在一场出于公开侮辱你的决斗中杀死了更有权势的家族的卓尔。死者的家族发誓要摧毁你的家族，除非你人头落地。你的血亲们强迫你离开他们。你想着他们为什么会变成这样。 | AW5: 致幻物质 | AX5: 夏是大胆与进犯的季节，为无拘无束的精力所填满。 | AY5: 你将上好的食物存储起来。因为你不喜欢连这点舒适的用品都失去。 | AZ5: 你在物质享受上穷奢极欲。 | BA5: 花了一便士就是永远弄丢了一便士。 | BB5: 你只会指出他人计划中的瑕疵。 | BC5: 你总是心浮气躁、坐立不安。 | BD5: 任何值得做的事情都值得不断地重复之。 | BE5: 你往往会先加以恐吓，因为你觉得通过展示力量来避免战斗总好过伤害别人。 | BF5: 你的怒火载着你披荆斩棘。 | BG5: 你会把梦中的逻辑应用到日常生活中 | BH5: 你的村庄被来自卓姆的怪物摧毁了，因而你开始在世界中找寻一个新的落脚点。 | BI5: 你试图将战时纪律运用到每一种情况中。 | BJ5: 你在与一个私人对手进行仇杀，试图在战斗或商业中击败他们。 | BK5: 由於不寻常的三团议会法律的扭曲，你与许多其他的孩子共享相同的名字，你在法律上被认为是同一个人。 | BL5: 你们的小科拉瓦社区只有在萨恩的贫民窟里才得以生存，你们互相给予了亲密的、像家人一样的支持。 | BM5: 你喜欢自吹自擂，你总是夸大自己的奇遇。 | BN5: 一个来自恶魔荒原的野蛮人从残酷的生活中忏悔，并希望为过去的罪恶赎罪 | BO5: 脑脊液 | BP5: 一条寄生虫寄生在你体内，你听任于它的饥渴。 | BQ5: 孩童时期你遭受了诅咒。与森林中的精魂们打交道导致你被转变为巫咒之子，并且这种诅咒无法被解除。 | BR5: 回忆中传来过去一位亲近你的人的声音。他们是怎么指导你的？ | BS5: 一层闪闪发光的雾一直环绕着你。 | BT5: 虎人
A6: 龙裔 | B6: =IF(综合数据!B11=TRUE,"龙国血统","") -> 龙国血统 | C6: =IF(综合数据!B11=TRUE,"瑞雯奈特","") -> 瑞雯奈特 | D6: =IF(综合数据!B16=TRUE,"色彩龙血统","") -> 色彩龙血统 | E6: =IF(综合数据!B16=TRUE,"宝石龙血统","") -> 宝石龙血统 | F6: =IF(综合数据!B16=TRUE,"金属龙血统","") -> 金属龙血统 | G6: ="" | H6: ="" | I6: ="" | J6: ="" | K6: ="" | L6: ="" | M6: ="" | N6: ="" | O6: ="" | R6: 巨型 | S6: {=INDEX(A:A,SMALL(IF($A$2:$A$45<>"",ROW($2:$45),46),ROW(A5)))&""} -> 龙裔 | T6: =INDEX($B$2:$K$45,$T$2,4) -> #N/A | U6: {=INDEX(T:T,SMALL(IF($T$3:$T$15<>"",ROW($3:$15),16),ROW(T5)))&""} -> #N/A | W6: 属性值加成 | X6: =IF(T18=0,"",IF(V4=0,VLOOKUP($V$3,$AI:$AJ,2,0),VLOOKUP($V$4,$AI:$AJ,2,0))) -> #N/A | Z6: =IFERROR(IF(OR($W10="",COUNTIF($AB$2:$AB$15,$W10)),"",W10),"") | AA6: {=INDEX(Z:Z,SMALL(IF($Z$2:$Z$16<>"",ROW($2:$16),17),ROW(Z5)))&""} | AB6: =IF(主要!$Z88="",0,主要!$Z88) -> 罗伊纳的图书馆 | AC6: =IFERROR(VLOOKUP($AB6,$W$6:$X$27,2,0),"") | AD6: =IF($AB6=0,"",COUNTIF($AB$2:$AB$15,$AB6)) -> 1 | AE6: 警戒龙纹 | AG6: 11 | AH6: 13 | AI6: 高等精灵 | AJ6: 敏捷+2，智力+1 | AK6: 中型 | AL6: 基础步行速度为30尺 | AM6: 和精灵语 | AN6: 严厉的，主观判断的 | AO6: 你的头部环绕着鬼魂般的光环 | AP6: 你学会了笑。你用这个天赋来回应所有的情绪状况，以更好地适应你的同伴。 | AQ6: 一件平凡的东西 | AR6: 当你高兴时会发出响亮的咕噜声。 | AS6: 陆上世界是个奇妙的地方，你把它的所有细节都记在了一本日记里。 | AT6: 一个金色的罗盘，它会指向10里内最近的通往妖精荒原的传送点 | AU6: 你的父亲认为你太弱小了，没有办法作为一个冒险者生存下来，但是他错了，而你会证明这一点。 | AV6: 你的一位密友被怀疑为伊莉丝翠的信徒。她圈子里的所有人都被怀疑。逃跑便是默认了指控，尽管你对此一无所知，但若你留在此处，你会被献祭给罗丝。 | AW6: 高品质奴隶与活祭 | BG6: 你在与梦族商量事情时会不自觉地大声说出 | BH6: 作为黄泉巨龙会的信徒，你相信，杀死强大的敌人是唯一的通往深藏在地底空心世界中的天堂的道路。为了寻找有价值的敌人，你冒险越过了湿地。 | BI6: 你不知道怎么控制自己的情绪，容易产生急剧的情绪爆发。 | BJ6: 你在寻找一个传说中的矮人神器，几个世纪前被一个坎纳斯贵族偷走了。 | BK6: 你已经获得了一个包含大量奇怪代码文本的法术碎片。 | BL6: 你是瑟雷恩社区的一员，他们对银焰教会的热爱使你将团结餐会扩展到非科拉瓦。 | BM6: 你戴着一个面具，你相信它保存着你以前恐龙坐骑的灵魂。你喜欢和它说话。 | BN6: 一个来自埃鲁登原野的善良德鲁伊他想了解科瓦雷地区的植物和动物 | BO6: 心灵能量 | BP6: 一场惨剧中止了你转变为不朽者的进程。 | BQ6: 你原本是一位精类生物，一场事故改变了你，并迫使你离开了家乡。 | BR6: 你回想起一件你过去曾享受，但现在却无法忍受的事物。它是什么？为什么你现在不喜欢了？ | BS6: 你的额头上有一根灵体角，就像小型的独角兽角。 | BT6: 狼人（类似狼）
A7: 侏儒 | B7: 森林侏儒 | C7: 岩侏儒 | D7: =IF(OR(综合数据!B8=TRUE,综合数据!B18=TRUE),"地底侏儒","") -> 地底侏儒 | E7: =IF(综合数据!B10=TRUE,"抄录龙纹","") -> 抄录龙纹 | F7: ="" | G7: ="" | H7: ="" | I7: ="" | J7: ="" | K7: ="" | L7: ="" | M7: ="" | ... O7: ="" | R7: 超巨型 | S7: {=INDEX(A:A,SMALL(IF($A$2:$A$45<>"",ROW($2:$45),46),ROW(A6)))&""} -> 侏儒 | T7: =INDEX($B$2:$K$45,$T$2,5) -> #N/A | U7: {=INDEX(T:T,SMALL(IF($T$3:$T$15<>"",ROW($3:$15),16),ROW(T6)))&""} -> #N/A | W7: 体型 | X7: =IF(T18=0,"",IF(V4=0,VLOOKUP($V$3,$AI:$AK,3,0),VLOOKUP($V$4,$AI:$AK,3,0))) -> #N/A | Z7: =IFERROR(IF(OR($W11="",COUNTIF($AB$2:$AB$15,$W11)),"",W11),"") | AA7: {=INDEX(Z:Z,SMALL(IF($Z$2:$Z$16<>"",ROW($2:$16),17),ROW(Z6)))&""} | AB7: =IF(主要!$Z89="",0,主要!$Z89) -> 额外专长 | AC7: =IFERROR(VLOOKUP($AB7,$W$6:$X$27,2,0),"") | AD7: =IF($AB7=0,"",COUNTIF($AB$2:$AB$15,$AB7)) -> 1 | AE7: 精灵 | AF7: =AF2+1 -> 2 | AG7: 1 | AH7: 4 | AI7: 木精灵 | AJ7: 敏捷+2，感知+1 | AK7: =AK$6 -> 中型 | AL7: =AL$6 -> 基础步行速度为30尺 | AM7: =AM$6 -> 和精灵语 | AN7: 仁慈的，父母般的 | AO7: 你的皮肤上闪烁着彩虹 | AP7: 你还是不懂隐喻是怎么起作用的。不过这并不妨碍你在每一个机会上使用它们。 | AQ7: 一件魔法物品 | AR7: 你让一个小毛线球缠在手上并不断地摆弄着。 | AS7: 你误以为陆上住民都知道你的种族的历史并且印象深刻。 | AT7: 一个银色的小陀螺，一旦它开始转动，那么在被人为打断前就会一直转下去 | AU7: 只有那些成就伟业者才会在他们死后被长久铭记。诗人们将会为你的丰功伟绩而喝彩。 | AV7: 你是一组被埋伏了的地表突击队的队员之一，然后你被抓住了。在被监禁的几年里，你知道了罗丝的祭司告诉你的关于地表世界的一切都是谎言，现在你要自己体验这里的真相。 | AW7: 从对地表突袭中获得的物品 | BG7: 你压抑自己的情绪，依靠逻辑办事 | BH7: 你的家族与萨拉释克家族合作，你被招募为赏金猎人或调查员，即使你并非家族成员。 | BI7: 你无法理解衣服除了实用性质以外的意义，并认为一个生物的穿着代表着他的功能。 | BJ7: 你想聚集可以帮助你探索古老废墟下祖先家园的勇士们。 | BK7: 你知道一个被通缉的战犯的位置，你一直在决定是把他们交出来，还是用你的沉默来换取什麽。 | BL7: 你的科拉瓦社区是一艘拉扎尔船的船员。 | BM7: 你不了解“事实”的概念。对你来说，每件事都是一个故事，而真相就在你如何讲述它。 | BN7: 一个来自坎纳斯的牧师，他渴望学习死灵术--当然是为了最崇高的目标 | BO7: 梦 | BP7: 你是一位被削弱的异界存在，满足你的饥饿感能加快你的恢复。 | BQ7: 一个被侮慢的德鲁伊转变了你，并将你与一棵神圣的树绑定，只要这棵树还结果，你就只能以这样的姿态活下去。 | BR7: 回忆起生动的气味和感觉。你要做些什么事情来重现这一经历呢？ | BS7: 你有着昆虫的腿。 | BT7: 狼人（类似犬）
A8: 半精灵 | B8: =IF(综合数据!B5=TRUE,"半木精灵","") -> 半木精灵 | C8: =IF(综合数据!B5=TRUE,"半月精灵","") -> 半月精灵 | D8: =IF(综合数据!B5=TRUE,"半日精灵","") -> 半日精灵 | E8: =IF(综合数据!B5=TRUE,"半卓尔精灵","") -> 半卓尔精灵 | F8: =IF(综合数据!B5=TRUE,"半水生精灵","") -> 半水生精灵 | G8: =IF(综合数据!B10=TRUE,"侦测龙纹","") -> 侦测龙纹 | H8: =IF(综合数据!B10=TRUE,"暴风龙纹","") -> 暴风龙纹 | I8: ="" | J8: ="" | K8: ="" | L8: ="" | M8: ="" | N8: ="" | O8: ="" | S8: {=INDEX(A:A,SMALL(IF($A$2:$A$45<>"",ROW($2:$45),46),ROW(A7)))&""} -> 半精灵 | T8: =INDEX($B$2:$K$45,$T$2,6) -> #N/A | U8: {=INDEX(T:T,SMALL(IF($T$3:$T$15<>"",ROW($3:$15),16),ROW(T7)))&""} -> #N/A | W8: 速度 | X8: =IF(T18=0,"",IF(V4=0,VLOOKUP($V$3,$AI:$AL,4,0),VLOOKUP($V$4,$AI:$AL,4,0))) -> #N/A | Z8: =IFERROR(IF(OR($W12="",COUNTIF($AB$2:$AB$15,$W12)),"",W12),"") | AA8: {=INDEX(Z:Z,SMALL(IF($Z$2:$Z$16<>"",ROW($2:$16),17),ROW(Z7)))&""} | AB8: =IF(主要!$Z90="",0,主要!$Z90) -> 0 | AC8: =IFERROR(VLOOKUP($AB8,$W$6:$X$27,2,0),"") | AD8: =IF($AB8=0,"",COUNTIF($AB$2:$AB$15,$AB8)) | AE8: 高等精灵 | AG8: 5 | AH8: 7 | AI8: 黑暗精灵 | AJ8: 敏捷+2，魅力+1 | AK8: =AK$6 -> 中型 | AL8: =AL$6 -> 基础步行速度为30尺 | AM8: =AM$6 -> 和精灵语 | AP8: 你欣赏软弱的类人生物意识到需要用链甲和剑才配得上你与生俱来的礼物。 | AQ8: 一处场所 | AR8: 你总是在负债，因为你把你的黄金都花在豪华的聚会上和送给朋友了。 | AT8: 一只用搪瓷，金丝与奇石制成的鸣鸟，当你用精灵语说出这只鸣鸟的名字时，它会开始歌唱。 | AU8: 你私底下爱上了队伍中的一位成员，你不能忍受哪怕只是想到那个人会受伤。 | AV8: 你在一生中都对你同胞的残忍行径感到陌生与害怕。你得到的第一个机会是自愿参加一次对地表的突袭，然后你抛弃了队伍并留在了后面。现在你不管到哪里去都被憎恨着、厌恶着，但至少你找到了一小组信任并支持彼此的冒险同伴。 | AW8: 低价类人奴隶 | BG8: 你周围的情绪会强烈地影响到你 | BH8: 你们家族的首领对另一个家族犯了大错，这个家族现在发誓要消灭你们家族的每一个成员。还有什么比现在更好的看外面世界的时机呢？ | BI8: 你对自己的外表很在意，总是在擦亮自己的装甲和向他人吹嘘。 | BJ8: 你拒绝了你的氏族对异变魔魔法的态度，招致了强大矮人的敌意。 | BK8: 你一直在卖假的藏宝图，但现在你可能找到了一张真的。 | BL8: 你是位於坎纳斯的一个小科拉瓦社区的一员，这个社区对死亡和你艾伦诺祖先的做法很着迷，把你的团结餐会变成了对死亡的残酷庆祝。 | BM8: 你会为那些为小型人们设计的建筑和工具而烦恼。 | BN8: 一个来自拉扎尔邦联的海盗吟游诗人，他热爱海中的棚屋，但也想让歌曲中伟大英雄的事蹟永垂不朽 | BO8: 生命精华 | BP8: 你双亲中的一位是吸血鬼。 | BS8: 你闻起来像是刚出炉的布朗尼。
A9: 半兽人 | B9: =IF(综合数据!B10=TRUE,"探索龙纹","") -> 探索龙纹 | C9: =IF(综合数据!B19=TRUE,"阿芒凯牛头怪","") | D9: ="" | E9: ="" | F9: ="" | G9: ="" | H9: ="" | I9: ="" | J9: ="" | K9: ="" | ... O9: ="" | S9: {=INDEX(A:A,SMALL(IF($A$2:$A$45<>"",ROW($2:$45),46),ROW(A8)))&""} -> 半兽人 | T9: =INDEX($B$2:$K$45,$T$2,7) -> #N/A | U9: {=INDEX(T:T,SMALL(IF($T$3:$T$15<>"",ROW($3:$15),16),ROW(T8)))&""} -> #N/A | W9: 语言 | X9: =IF(T18=0,"","能说、读、写通用语"&IF(V4=0,VLOOKUP($V$3,$AI:$AM,5,0),VLOOKUP($V$4,$AI:$AM,5,0))) -> #N/A | Z9: =IFERROR(IF(OR($W13="",COUNTIF($AB$2:$AB$15,$W13)),"",W13),"") | AA9: {=INDEX(Z:Z,SMALL(IF($Z$2:$Z$16<>"",ROW($2:$16),17),ROW(Z8)))&""} | AB9: =IF(主要!$Z91="",0,主要!$Z91) -> 0 | AC9: =IFERROR(VLOOKUP($AB9,$W$6:$X$27,2,0),"") | AD9: =IF($AB9=0,"",COUNTIF($AB$2:$AB$15,$AB9)) | AE9: 木精灵 | AG9: 8 | AH9: 10 | AI9: 雅灵 | AJ9: 自选两项属性分别+2/+1或自选三项属性+1 | AK9: =AK$6 -> 中型 | AL9: =AL$6 -> 基础步行速度为30尺 | AM9: ，以及任意一门自选语言 | AP9: 你喜欢在你的食物还在蠕动的时候吃了它。 | AQ9: 一个传说或者故事 | AR9: 当谈论你追求的东西时，你说话飞快，从不停顿，让别人没法明白你。 | AT9: 一只用搪瓷制作的花朵，当它被放进一个人的头发里时，它会变成活的花并用一支真的花藤系住穿戴者的头发。摘下这支藤蔓上的花会让它再次变成非活物。 | AU9: 当你出生之时，你的祖母预言你会统治一个人类王国。你正在追寻这个命运。 | AV9: 在灰矮人为奴隶与财宝袭击队伍时，你是那支往其它卓尔城市传递外交信息的使节团的一员。只有你和另一个守卫逃脱了。如果你回家，你会被毒死或因失败遭到更可怕的处罚，成为一名佣兵是你最好的选择。 | AW9: 幽暗地域的地图 | BG9: 只要有可能，你更倾向于通过非暴力手段解决问题 | BH9: 作为一名调查员，你的工作让你踏上了一条远离湿地的神秘之路。 | BI9: 战争是对你来说唯一有意义的事，所以你一直都在追求战斗。 | BJ9: 你想知道其他科瓦雷人--尤其是哥布林和兽人--是如何与异变魔作战的。 | BK9: 你获得了一个龙晶矿坑的控股权，这个矿坑很久以前就被废弃了。但是为什麽呢?狗头人吗?异怪?真相只有一个! | BL9: 你是一个微型科拉瓦社区的一部分，生活在一个意想不到的地方，比如卓姆、达贡，甚至是恶魔荒原。你的人民努力寻找与当地人的共同点。 | BM9: 你要为你百姓所受的恶报仇。 | BN9: 一个被训练在夸巴拉丛林狩猎的游侠，对龙怀恨在心。 | BP9: 一场极端的实验改变了你的身体，让你以他人的生命体液维生。 | BS9: 一种明显的、无害的寒意环绕着你。
A10: 提夫林 | B10: =IF(综合数据!B5=TRUE,"提夫林变体","") -> 提夫林变体 | C10: =IF(综合数据!B8=TRUE,"巴尔泽布","") -> 巴尔泽布 | D10: =IF(综合数据!B8=TRUE,"迪斯帕特","") -> 迪斯帕特 | E10: =IF(综合数据!B8=TRUE,"菲尔娜","") -> 菲尔娜 | F10: =IF(综合数据!B8=TRUE,"格莱西雅","") -> 格莱西雅 | G10: =IF(综合数据!B8=TRUE,"莱维斯图斯","") -> 莱维斯图斯 | H10: =IF(综合数据!B8=TRUE,"马曼","") -> 马曼 | I10: =IF(综合数据!B8=TRUE,"墨菲斯托菲利斯","") -> 墨菲斯托菲利斯 | J10: =IF(综合数据!B8=TRUE,"扎瑞尔","") -> 扎瑞尔 | K10: ="" | L10: ="" | M10: ="" | N10: ="" | O10: ="" | S10: {=INDEX(A:A,SMALL(IF($A$2:$A$45<>"",ROW($2:$45),46),ROW(A9)))&""} -> 提夫林 | T10: =INDEX($B$2:$K$45,$T$2,8) -> #N/A | U10: {=INDEX(T:T,SMALL(IF($T$3:$T$15<>"",ROW($3:$15),16),ROW(T9)))&""} -> #N/A | V10: =IF($V9+1>$Y$3,IF($X$4+$Y9>$Y$4,"",$X$4+$Y9),$V9+1) -> #N/A | W10: =INDEX($B$52:$AD$147,W$4,$V10) -> #N/A | X10: =INDEX($B$52:$AD$147,W$3,$V10) -> #N/A | Y10: =IF($V9+1>$Y$3,$Y9+1,0) -> #N/A | Z10: =IFERROR(IF(OR($W14="",COUNTIF($AB$2:$AB$15,$W14)),"",W14),"") | AA10: {=INDEX(Z:Z,SMALL(IF($Z$2:$Z$16<>"",ROW($2:$16),17),ROW(Z9)))&""} | AB10: =IF(主要!$Z92="",0,主要!$Z92) -> 0 | AC10: =IFERROR(VLOOKUP($AB10,$W$6:$X$27,2,0),"") | AD10: =IF($AB10=0,"",COUNTIF($AB$2:$AB$15,$AB10)) | AE10: 黑暗精灵 | AG10: 11 | AH10: 14 | AI10: 海精灵 | AJ10: =AJ9 -> 自选两项属性分别+2/+1或自选三项属性+1 | AK10: =AK$6 -> 中型 | AL10: =AL$6 -> 基础步行速度为30尺 | AM10: =AM9 -> ，以及任意一门自选语言 | AR10: 你按耐不住地想要独吞你感兴趣的东西。 | AW10: 毒药 | BG10: 你被勇士的精神体所影响，会为了任何高尚的事业而奋斗 | BK10: 你的家庭正面临经济崩溃，他们给你买了保险。只有在你非自然死亡时才能理赔，他们鼓励你去寻找更危险的冒险。 | BL10: 你与林兰德家族或梅丹尼家族有联系，但你更感兴趣的是家族在支持科拉瓦社区方面所扮演的角色，而不是其公会的工作。 | BM10: 你永远不会忘记一个侮辱或伤害。 | BN10: 一个来自阴影湿地的契术师走了过来，在神智清醒的边缘摇摇欲坠，同时凝视着异变魔
A11: =IF(OR(综合数据!B6=TRUE,综合数据!B11=TRUE,综合数据!B18=TRUE),"阿斯莫","") -> 阿斯莫 | B11: ="" | C11: ="" | D11: ="" | E11: ="" | F11: ="" | G11: ="" | H11: ="" | I11: ="" | ... O11: ="" | S11: {=INDEX(A:A,SMALL(IF($A$2:$A$45<>"",ROW($2:$45),46),ROW(A10)))&""} -> 阿斯莫 | T11: =INDEX($B$2:$K$45,$T$2,9) -> #N/A | U11: {=INDEX(T:T,SMALL(IF($T$3:$T$15<>"",ROW($3:$15),16),ROW(T10)))&""} -> #N/A | V11: =IF($V10+1>$Y$3,IF($X$4+$Y10>$Y$4,"",$X$4+$Y10),$V10+1) -> #N/A | W11: =INDEX($B$52:$AD$147,W$4,$V11) -> #N/A | X11: =INDEX($B$52:$AD$147,W$3,$V11) -> #N/A | Y11: =IF($V10+1>$Y$3,$Y10+1,0) -> #N/A | Z11: =IFERROR(IF(OR($W15="",COUNTIF($AB$2:$AB$15,$W15)),"",W15),"") | AA11: {=INDEX(Z:Z,SMALL(IF($Z$2:$Z$16<>"",ROW($2:$16),17),ROW(Z10)))&""} | AB11: =IF(主要!$Z93="",0,主要!$Z93) -> 0 | AC11: =IFERROR(VLOOKUP($AB11,$W$6:$X$27,2,0),"") | AD11: =IF($AB11=0,"",COUNTIF($AB$2:$AB$15,$AB11)) | AE11: 雅灵 | AG11: 15 | AH11: 15 | AI11: 影灵 | AJ11: =AJ9 -> 自选两项属性分别+2/+1或自选三项属性+1 | AK11: =AK$6 -> 中型 | AL11: =AL$6 -> 基础步行速度为30尺 | AM11: =AM9 -> ，以及任意一门自选语言 | AR11: 你说话的时候会将你发现过的传说与故事当梗用到你的话里。 | AW11: 运输用爬行动物 | BG11: 你被梦境之暗的阴谋纠缠 | BK11: 你在兜售一个延长寿命的计划，让客户被梅杜莎石化，然後再恢复。 | BL11: 你在维伦那旅行，希望有一天能证明你配得上一个守护灵祖先。 | BM11: 你把一切都归因於灵魂的工作。 | BN11: 一个瑟雷恩的银焰教会圣骑士，他在寻找一些东西来证明支撑信仰的真理。
A12: =IF(OR(综合数据!B6=TRUE,综合数据!B11=TRUE,综合数据!B18=TRUE),"费尔伯格人","") -> 费尔伯格人 | B12: ="" | C12: ="" | D12: ="" | E12: ="" | F12: ="" | G12: ="" | H12: ="" | I12: ="" | ... O12: ="" | S12: {=INDEX(A:A,SMALL(IF($A$2:$A$45<>"",ROW($2:$45),46),ROW(A11)))&""} -> 费尔伯格人 | T12: =INDEX($B$2:$K$45,$T$2,10) -> #N/A | U12: {=INDEX(T:T,SMALL(IF($T$3:$T$15<>"",ROW($3:$15),16),ROW(T11)))&""} -> #N/A | V12: =IF($V11+1>$Y$3,IF($X$4+$Y11>$Y$4,"",$X$4+$Y11),$V11+1) -> #N/A | W12: =INDEX($B$52:$AD$147,W$4,$V12) -> #N/A | X12: =INDEX($B$52:$AD$147,W$3,$V12) -> #N/A | Y12: =IF($V11+1>$Y$3,$Y11+1,0) -> #N/A | Z12: =IFERROR(IF(OR($W16="",COUNTIF($AB$2:$AB$15,$W16)),"",W16),"") | AA12: {=INDEX(Z:Z,SMALL(IF($Z$2:$Z$16<>"",ROW($2:$16),17),ROW(Z11)))&""} | AB12: =IF(主要!$Z94="",0,主要!$Z94) -> 0 | AC12: =IFERROR(VLOOKUP($AB12,$W$6:$X$27,2,0),"") | AD12: =IF($AB12=0,"",COUNTIF($AB$2:$AB$15,$AB12)) | AE12: 海精灵 | AG12: 16 | AH12: 18 | AI12: 阴影龙纹 | AJ12: 敏捷+2，魅力+1 | AK12: =AK$6 -> 中型 | AL12: =AL$6 -> 基础步行速度为30尺 | AM12: =AM$6 -> 和精灵语
A13: =IF(OR(综合数据!B6=TRUE,综合数据!B11=TRUE,综合数据!B18=TRUE),"歌利亚","") -> 歌利亚 | B13: ="" | C13: ="" | D13: ="" | E13: ="" | F13: ="" | G13: ="" | H13: ="" | I13: ="" | ... O13: ="" | S13: {=INDEX(A:A,SMALL(IF($A$2:$A$45<>"",ROW($2:$45),46),ROW(A12)))&""} -> 歌利亚 | T13: =IF(综合数据!B15=TRUE,"半血裔","") -> 半血裔 | U13: {=INDEX(T:T,SMALL(IF($T$3:$T$15<>"",ROW($3:$15),16),ROW(T12)))&""} -> #N/A | V13: =IF($V12+1>$Y$3,IF($X$4+$Y12>$Y$4,"",$X$4+$Y12),$V12+1) -> #N/A | W13: =INDEX($B$52:$AD$147,W$4,$V13) -> #N/A | X13: =INDEX($B$52:$AD$147,W$3,$V13) -> #N/A | Y13: =IF($V12+1>$Y$3,$Y12+1,0) -> #N/A | Z13: =IFERROR(IF(OR($W17="",COUNTIF($AB$2:$AB$15,$W17)),"",W17),"") | AA13: {=INDEX(Z:Z,SMALL(IF($Z$2:$Z$16<>"",ROW($2:$16),17),ROW(Z12)))&""} | AB13: =IF(主要!$Z95="",0,主要!$Z95) -> 0 | AC13: =IFERROR(VLOOKUP($AB13,$W$6:$X$27,2,0),"") | AD13: =IF($AB13=0,"",COUNTIF($AB$2:$AB$15,$AB13)) | AE13: 影灵 | AG13: 19 | AH13: 20 | AI13: 苍白精灵 | AJ13: 敏捷+2，感知+1 | AK13: =AK$6 -> 中型 | AL13: =AL$6 -> 基础步行速度为30尺 | AM13: =AM$6 -> 和精灵语
A14: =IF(OR(综合数据!B6=TRUE,综合数据!B11=TRUE,综合数据!B18=TRUE),"天狗","") -> 天狗 | B14: ="" | C14: ="" | D14: ="" | E14: ="" | F14: ="" | G14: ="" | H14: ="" | I14: ="" | ... O14: ="" | S14: {=INDEX(A:A,SMALL(IF($A$2:$A$45<>"",ROW($2:$45),46),ROW(A13)))&""} -> 天狗 | T14: =IF(综合数据!B15=TRUE,"巫咒之子","") -> 巫咒之子 | U14: {=INDEX(T:T,SMALL(IF($T$3:$T$15<>"",ROW($3:$15),16),ROW(T13)))&""} -> #N/A | V14: =IF($V13+1>$Y$3,IF($X$4+$Y13>$Y$4,"",$X$4+$Y13),$V13+1) -> #N/A | W14: =INDEX($B$52:$AD$147,W$4,$V14) -> #N/A | X14: =INDEX($B$52:$AD$147,W$3,$V14) -> #N/A | Y14: =IF($V13+1>$Y$3,$Y13+1,0) -> #N/A | Z14: =IFERROR(IF(OR($W18="",COUNTIF($AB$2:$AB$15,$W18)),"",W18),"") | AA14: {=INDEX(Z:Z,SMALL(IF($Z$2:$Z$16<>"",ROW($2:$16),17),ROW(Z13)))&""} | AB14: =IF(主要!$Z96="",0,主要!$Z96) -> 0 | AC14: =IFERROR(VLOOKUP($AB14,$W$6:$X$27,2,0),"") | AD14: =IF($AB14=0,"",COUNTIF($AB$2:$AB$15,$AB14)) | AE14: 阴影龙纹 | AG14: 21 | AH14: 23 | AI14: 轻足半身人 | AJ14: 敏捷+2，魅力+1 | AK14: 小型 | AL14: 基础步行速度为25尺 | AM14: 和半身人语
A15: =IF(OR(综合数据!B6=TRUE,综合数据!B18=TRUE),"蜥蜴人","") -> 蜥蜴人 | B15: ="" | C15: ="" | D15: ="" | E15: ="" | F15: ="" | G15: ="" | H15: ="" | I15: ="" | ... O15: ="" | S15: {=INDEX(A:A,SMALL(IF($A$2:$A$45<>"",ROW($2:$45),46),ROW(A14)))&""} -> 蜥蜴人 | T15: =IF(综合数据!B15=TRUE,"重生者","") -> 重生者 | V15: =IF($V14+1>$Y$3,IF($X$4+$Y14>$Y$4,"",$X$4+$Y14),$V14+1) -> #N/A | W15: =INDEX($B$52:$AD$147,W$4,$V15) -> #N/A | X15: =INDEX($B$52:$AD$147,W$3,$V15) -> #N/A | Y15: =IF($V14+1>$Y$3,$Y14+1,0) -> #N/A | Z15: =IFERROR(IF(OR($W19="",COUNTIF($AB$2:$AB$15,$W19)),"",W19),"") | AA15: {=INDEX(Z:Z,SMALL(IF($Z$2:$Z$16<>"",ROW($2:$16),17),ROW(Z14)))&""} | AB15: =IF(主要!$Z97="",0,主要!$Z97) -> 0 | AC15: =IFERROR(VLOOKUP($AB15,$W$6:$X$27,2,0),"") | AD15: =IF($AB15=0,"",COUNTIF($AB$2:$AB$15,$AB15)) | AE15: 苍白精灵 | AG15: 24 | AH15: 25 | AI15: 敦实半身人 | AJ15: 敏捷+2，体质+1 | AK15: =AK$14 -> 小型 | AL15: =AL$14 -> 基础步行速度为25尺 | AM15: =AM$14 -> 和半身人语
A16: =IF(OR(综合数据!B6=TRUE,综合数据!B11=TRUE,综合数据!B18=TRUE),"斑猫人","") -> 斑猫人 | B16: ="" | C16: ="" | D16: ="" | E16: ="" | F16: ="" | G16: ="" | H16: ="" | I16: ="" | ... O16: ="" | S16: {=INDEX(A:A,SMALL(IF($A$2:$A$45<>"",ROW($2:$45),46),ROW(A15)))&""} -> 斑猫人 | V16: =IF($V15+1>$Y$3,IF($X$4+$Y15>$Y$4,"",$X$4+$Y15),$V15+1) -> #N/A | W16: =INDEX($B$52:$AD$147,W$4,$V16) -> #N/A | X16: =INDEX($B$52:$AD$147,W$3,$V16) -> #N/A | Y16: =IF($V15+1>$Y$3,$Y15+1,0) -> #N/A | Z16: =IFERROR(IF(OR($W20="",COUNTIF($AB$2:$AB$15,$W20)),"",W20),"") | AA16: {=INDEX(Z:Z,SMALL(IF($Z$2:$Z$16<>"",ROW($2:$16),17),ROW(Z15)))&""} | AB16: 重复特性 | AC16: =COUNTIF(AD2:AD15,">1") -> 0 | AD16: 动物强化 | AE16: 半身人 | AF16: =AF7+1 -> 3 | AG16: 1 | AH16: 3 | AI16: 鬼智半身人 | AJ16: 敏捷+2，感知+1 | AK16: =AK$14 -> 小型 | AL16: =AL$14 -> 基础步行速度为25尺 | AM16: =AM$14 -> 和半身人语
A17: =IF(OR(综合数据!B6=TRUE,综合数据!B18=TRUE),"梭螺鱼人","") -> 梭螺鱼人 | B17: ="" | C17: ="" | D17: ="" | E17: ="" | F17: ="" | G17: ="" | H17: ="" | I17: ="" | ... O17: ="" | S17: {=INDEX(A:A,SMALL(IF($A$2:$A$45<>"",ROW($2:$45),46),ROW(A16)))&""} -> 梭螺鱼人 | T17: 亚种错误 | U17: 未选亚种 | V17: =IF($V16+1>$Y$3,IF($X$4+$Y16>$Y$4,"",$X$4+$Y16),$V16+1) -> #N/A | W17: =INDEX($B$52:$AD$147,W$4,$V17) -> #N/A | X17: =INDEX($B$52:$AD$147,W$3,$V17) -> #N/A | Y17: =IF($V16+1>$Y$3,$Y16+1,0) -> #N/A | AB17: 互斥特性 | AC17: =COUNTIF(AC18:AC25,">1") -> 0 | AD17: =IF(AND(V2<5,AD21>0),2,IF(AD19+AD21>2,2,IF(AD21>1,2,0))) -> 0 | AE17: 轻足半身人 | AG17: 4 | AH17: 4 | AI17: 医疗龙纹 | AJ17: 敏捷+2，感知+1 | AK17: =AK$14 -> 小型 | AL17: =AL$14 -> 基础步行速度为25尺 | AM17: =AM$14 -> 和半身人语
